EEEEEEEEEEEEEEEEEEE
E
======================================================================
ERROR: test_console (unittest.loader._FailedTest.test_console)
======================================================================
ERROR: test_console (unittest.loader._FailedTest.test_console)
----------------------------------------------------------------------
ImportError: Failed to import test module: test_console
Traceback (most recent call last):
  File "/usr/lib/python3.11/site-packages/sqlalchemy/engine/base.py", line 3361, in _wrap_pool_connect
    return fn()
           ^^^^
  File "/usr/lib/python3.11/site-packages/sqlalchemy/pool/base.py", line 325, in connect
    return _ConnectionFairy._checkout(self)
           ^^^^^^^^^^^^^^^^^^^^^^^^^^^^^^^^
  File "/usr/lib/python3.11/site-packages/sqlalchemy/pool/base.py", line 888, in _checkout
    fairy = _ConnectionRecord.checkout(pool)
            ^^^^^^^^^^^^^^^^^^^^^^^^^^^^^^^^
  File "/usr/lib/python3.11/site-packages/sqlalchemy/pool/base.py", line 491, in checkout
    rec = pool._do_get()
          ^^^^^^^^^^^^^^
  File "/usr/lib/python3.11/site-packages/sqlalchemy/pool/impl.py", line 145, in _do_get
    with util.safe_reraise():
  File "/usr/lib/python3.11/site-packages/sqlalchemy/util/langhelpers.py", line 70, in __exit__
    compat.raise_(
  File "/usr/lib/python3.11/site-packages/sqlalchemy/util/compat.py", line 210, in raise_
    raise exception
  File "/usr/lib/python3.11/site-packages/sqlalchemy/pool/impl.py", line 143, in _do_get
    return self._create_connection()
           ^^^^^^^^^^^^^^^^^^^^^^^^^
  File "/usr/lib/python3.11/site-packages/sqlalchemy/pool/base.py", line 271, in _create_connection
    return _ConnectionRecord(self)
           ^^^^^^^^^^^^^^^^^^^^^^^
  File "/usr/lib/python3.11/site-packages/sqlalchemy/pool/base.py", line 386, in __init__
    self.__connect()
  File "/usr/lib/python3.11/site-packages/sqlalchemy/pool/base.py", line 684, in __connect
    with util.safe_reraise():
  File "/usr/lib/python3.11/site-packages/sqlalchemy/util/langhelpers.py", line 70, in __exit__
    compat.raise_(
  File "/usr/lib/python3.11/site-packages/sqlalchemy/util/compat.py", line 210, in raise_
    raise exception
  File "/usr/lib/python3.11/site-packages/sqlalchemy/pool/base.py", line 680, in __connect
    self.dbapi_connection = connection = pool._invoke_creator(self)
                                         ^^^^^^^^^^^^^^^^^^^^^^^^^^
  File "/usr/lib/python3.11/site-packages/sqlalchemy/engine/create.py", line 578, in connect
    return dialect.connect(*cargs, **cparams)
           ^^^^^^^^^^^^^^^^^^^^^^^^^^^^^^^^^^
  File "/usr/lib/python3.11/site-packages/sqlalchemy/engine/default.py", line 598, in connect
    return self.dbapi.connect(*cargs, **cparams)
           ^^^^^^^^^^^^^^^^^^^^^^^^^^^^^^^^^^^^^
  File "/usr/lib/python3.11/site-packages/MySQLdb/__init__.py", line 123, in Connect
    return Connection(*args, **kwargs)
           ^^^^^^^^^^^^^^^^^^^^^^^^^^^
  File "/usr/lib/python3.11/site-packages/MySQLdb/connections.py", line 185, in __init__
    super().__init__(*args, **kwargs2)
MySQLdb.OperationalError: (1045, "Access denied for user 'hbnb_test'@'localhost' (using password: YES)")

The above exception was the direct cause of the following exception:

Traceback (most recent call last):
  File "/usr/lib/python3.11/unittest/loader.py", line 419, in _find_test_path
    module = self._get_module_from_name(name)
             ^^^^^^^^^^^^^^^^^^^^^^^^^^^^^^^^
  File "/usr/lib/python3.11/unittest/loader.py", line 362, in _get_module_from_name
    __import__(name)
  File "/home/meta-bay/workspace/AirBnB_clone_v3/tests/test_console.py", line 6, in <module>
    import console
  File "/home/meta-bay/workspace/AirBnB_clone_v3/console.py", line 6, in <module>
    import models
  File "/home/meta-bay/workspace/AirBnB_clone_v3/models/__init__.py", line 13, in <module>
    storage = DBStorage()
              ^^^^^^^^^^^
  File "/home/meta-bay/workspace/AirBnB_clone_v3/models/engine/db_storage.py", line 41, in __init__
    Base.metadata.drop_all(self.__engine)
  File "/usr/lib/python3.11/site-packages/sqlalchemy/sql/schema.py", line 4959, in drop_all
    bind._run_ddl_visitor(
  File "/usr/lib/python3.11/site-packages/sqlalchemy/engine/base.py", line 3227, in _run_ddl_visitor
    with self.begin() as conn:
         ^^^^^^^^^^^^
  File "/usr----------------------------------------------------------------------
ImportError: Failed to import test module: test_console
Traceback (most recent call last):
  File "/usr/lib/python3.11/site-packages/sqlalchemy/engine/base.py", line 3361, in _wrap_pool_connect
    return fn()
           ^^^^
  File "/usr/lib/python3.11/site-packages/sqlalchemy/pool/base.py", line 325, in connect
    return _ConnectionFairy._checkout(self)
           ^^^^^^^^^^^^^^^^^^^^^^^^^^^^^^^^
  File "/usr/lib/python3.11/site-packages/sqlalchemy/pool/base.py", line 888, in _checkout
    fairy = _ConnectionRecord.checkout(pool)
            ^^^^^^^^^^^^^^^^^^^^^^^^^^^^^^^^
  File "/usr/lib/python3.11/site-packages/sqlalchemy/pool/base.py", line 491, in checkout
    rec = pool._do_get()
          ^^^^^^^^^^^^^^
  File "/usr/lib/python3.11/site-packages/sqlalchemy/pool/impl.py", line 145, in _do_get
    with util.safe_reraise():
  File "/usr/lib/python3.11/site-packages/sqlalchemy/util/langhelpers.py", line 70, in __exit__
    compat.raise_(
  File "/usr/lib/python3.11/site-packages/sqlalchemy/util/compat.py", line 210, in raise_
    raise exception
  File "/usr/lib/python3.11/site-packages/sqlalchemy/pool/impl.py", line 143, in _do_get
    return self._create_connection()
           ^^^^^^^^^^^^^^^^^^^^^^^^^
  File "/usr/lib/python3.11/site-packages/sqlalchemy/pool/base.py", line 271, in _create_connection
    return _ConnectionRecord(self)
           ^^^^^^^^^^^^^^^^^^^^^^^
  File "/usr/lib/python3.11/site-packages/sqlalchemy/pool/base.py", line 386, in __init__
    self.__connect()
  File "/usr/lib/python3.11/site-packages/sqlalchemy/pool/base.py", line 684, in __connect
    with util.safe_reraise():
  File "/usr/lib/python3.11/site-packages/sqlalchemy/util/langhelpers.py", line 70, in __exit__
    compat.raise_(
  File "/usr/lib/python3.11/site-packages/sqlalchemy/util/compat.py", line 210, in raise_
    raise exception
  File "/usr/lib/python3.11/site-packages/sqlalchemy/pool/base.py", line 680, in __connect
    self.dbapi_connection = connection = pool._invoke_creator(self)
                                         ^^^^^^^^^^^^^^^^^^^^^^^^^^
  File "/usr/lib/python3.11/site-packages/sqlalchemy/engine/create.py", line 578, in connect
    return dialect.connect(*cargs, **cparams)
           ^^^^^^^^^^^^^^^^^^^^^^^^^^^^^^^^^^
  File "/usr/lib/python3.11/site-packages/sqlalchemy/engine/default.py", line 598, in connect
    return self.dbapi.connect(*cargs, **cparams)
           ^^^^^^^^^^^^^^^^^^^^^^^^^^^^^^^^^^^^^
  File "/usr/lib/python3.11/site-packages/MySQLdb/__init__.py", line 123, in Connect
    return Connection(*args, **kwargs)
           ^^^^^^^^^^^^^^^^^^^^^^^^^^^
  File "/usr/lib/python3.11/site-packages/MySQLdb/connections.py", line 185, in __init__
    super().__init__(*args, **kwargs2)
MySQLdb.OperationalError: (1045, "Access denied for user 'hbnb_test'@'localhost' (using password: YES)")

The above exception was the direct cause of the following exception:

Traceback (most recent call last):
  File "/usr/lib/python3.11/unittest/loader.py", line 419, in _find_test_path
    module = self._get_module_from_name(name)
             ^^^^^^^^^^^^^^^^^^^^^^^^^^^^^^^^
  File "/usr/lib/python3.11/unittest/loader.py", line 362, in _get_module_from_name
    __import__(name)
  File "/home/meta-bay/workspace/AirBnB_clone_v3/tests/test_console.py", line 6, in <module>
    import console
  File "/home/meta-bay/workspace/AirBnB_clone_v3/console.py", line 6, in <module>
    import models
  File "/home/meta-bay/workspace/AirBnB_clone_v3/models/__init__.py", line 13, in <module>
    storage = DBStorage()
              ^^^^^^^^^^^
  File "/home/meta-bay/workspace/AirBnB_clone_v3/models/engine/db_storage.py", line 41, in __init__
    Base.metadata.drop_all(self.__engine)
  File "/usr/lib/python3.11/site-packages/sqlalchemy/sql/schema.py", line 4959, in drop_all
    bind._run_ddl_visitor(
  File "/usr/lib/python3.11/site-packages/sqlalchemy/engine/base.py", line 3227, in _run_ddl_visitor
    with self.begin() as conn:
         ^^^^^^^^^^^^
  File "/usr/lib/python3.11/site-packages/sqlalchemy/engine/base.py", line 3143, in begin
    conn = self.connect(close_with_result=close_with_result)
           ^^^^^^^^^^^^^^^^^^^^^^^^^^^^^^^^^^^^^^^^^^^^^^^^^
  File "/usr/lib/python3.11/site-packages/sqlalchemy/engine/base.py", line 3315, in connect
    return self._connection_cls(self, close_with_result=close_with_result)
           ^^^^^^^^^^^^^^^^^^^^^^^^^^^^^^^^^^^^^^^^^^^^^^^^^^^^^^^^^^^^^^^
  File "/usr/lib/python3.11/site-packages/sqlalchemy/engine/base.py", line 96, in __init__
    else engine.raw_connection()
         ^^^^^^^^^^^^^^^^^^^^^^^
  File "/usr/lib/python3.11/site-packages/sqlalchemy/engine/base.py", line 3394, in raw_connection
    return self._wrap_pool_connect(self.pool.connect, _connection)
           ^^^^^^^^^^^^^^^^^^^^^^^^^^^^^^^^^^^^^^^^^^^^^^^^^^^^^^^
  File "/usr/lib/python3.11/site-packages/sqlalchemy/engine/base.py", line 3364, in _wrap_pool_connect
    Connection._handle_dbapi_exception_noconnection(
  File "/usr/lib/python3.11/site-packages/sqlalchemy/engine/base.py", line 2198, in _handle_dbapi_exception_noconnection
    util.raise_(
  File "/usr/lib/python3.11/site-packages/sqlalchemy/util/compat.py", line 210, in raise_
    raise exception
  File "/usr/lib/python3.11/site-packages/sqlalchemy/engine/base.py", line 3361, in _wrap_pool_connect
    return fn()
           ^^^^
  File "/usr/lib/python3.11/site-packages/sqlalchemy/pool/base.py", line 325, in connect
    return _ConnectionFairy._checkout(self)
           ^^^^^^^^^^^^^^^^^^^^^^^^^^^^^^^^
  File "/usr/lib/python3.11/site-packages/sqlalchemy/pool/base.py", line 888, in _checkout
    fairy = _ConnectionRecord.checkout(pool)
            ^^^^^^^^^^^^^^^^^^^^^^^^^^^^^^^^
  File "/usr/lib/python3.11/site-packages/sqlalchemy/pool/base.py", line 491, in checkout
    rec = pool._do_get()
          ^^^^^^^^^^^^^^
  File "/usr/lib/python3.11/site-packages/sqlalchemy/pool/impl.py", line 145, in _do_get
    with util.safe_reraise():
  File "/usr/lib/python3.11/site-packages/sqlalchemy/util/langhelpers.py", line 70, in __exit__
    compat.raise_(
  File "/usr/lib/python3.11/site-packages/sqlalchemy/util/compat.py", line 210, in raise_
    raise exception
  File "/usr/lib/python3.11/site-packages/sqlalchemy/pool/impl.py", line 143, in _do_get
    return self._create_connection()
           ^^^^^^^^^^^^^^^^^^^^^^^^^
  File "/usr/lib/python3.11/site-packages/sqlalchemy/pool/base.py", line 271, in _create_connection
    return _ConnectionRecord(self)
           ^^^^^^^^^^^^^^^^^^^^^^^
  File "/usr/lib/python3.11/site-packages/sqlalchemy/pool/base.py", line 386, in __init__
    self.__connect()
  File "/usr/lib/python3.11/site-packages/sqlalchemy/pool/base.py", line 684, in __connect
    with util.safe_reraise():
  File "/usr/lib/python3.11/site-packages/sqlalchemy/util/langhelpers.py", line 70, in __exit__
    compat.raise_(
  File "/usr/lib/python3.11/site-packages/sqlalchemy/util/compat.py", line 210, in raise_
    raise exception
  File "/usr/lib/python3.11/site-packages/sqlalchemy/pool/base.py", line 680, in __connect
    self.dbapi_connection = connection = pool._invoke_creator(self)
                                         ^^^^^^^^^^^^^^^^^^^^^^^^^^
  File "/usr/lib/python3.11/site-packages/sqlalchemy/engine/create.py", line 578, in connect
    return dialect.connect(*cargs, **cparams)
           ^^^^^^^^^^^^^^^^^^^^^^^^^^^^^^^^^^
  File "/usr/lib/python3.11/site-packages/sqlalchemy/engine/default.py", line 598, in connect
    return self.dbapi.connect(*cargs, **cparams)
           ^^^^^^^^^^^^^^^^^^^^^^^^^^^^^^^^^^^^^
  File "/usr/lib/python3.11/site-packages/MySQLdb/__init__.py", line 123, in Connect
    return Connection(*args, **kwargs)
           ^^^^^^^^^^^^^^^^^^^^^^^^^^^
  File "/usr/lib/python3.11/site-packages/MySQLdb/connections.py", line 185, in __init__
    super().__init__(*args, **kwargs2)
sqlalchemy.exc.OperationalError: (MySQLdb.OperationalError) (1045, "Access denied for user 'hbnb_test'@'localhost' (using password: YES)")
(Background on this error at: https://sqlalche.me/e/14//lib/python3.11/site-packages/sqlalchemy/engine/base.py", line 3143, in begin
    conn = self.connect(close_with_result=close_with_result)
           ^^^^^^^^^^^^^^^^^^^^^^^^^^^^^^^^^^^^^^^^^^^^^^^^^
  File "/usr/lib/python3.11/site-packages/sqlalchemy/engine/base.py", line 3315, in connect
    return self._connection_cls(self, close_with_result=close_with_result)
           ^^^^^^^^^^^^^^^^^^^^^^^^^^^^^^^^^^^^^^^^^^^^^^^^^^^^^^^^^^^^^^^
  File "/usr/lib/python3.11/site-packages/sqlalchemy/engine/base.py", line 96, in __init__
    else engine.raw_connection()
         ^^^^^^^^^^^^^^^^^^^^^^^
  File "/usr/lib/python3.11/site-packages/sqlalchemy/engine/base.py", line 3394, in raw_connection
    return self._wrap_pool_connect(self.pool.connect, _connection)
           ^^^^^^^^^^^^^^^^^^^^^^^^^^^^^^^^^^^^^^^^^^^^^^^^^^^^^^^
  File "/usr/lib/python3.11/site-packages/sqlalchemy/engine/base.py", line 3364, in _wrap_pool_connect
    Connection._handle_dbapi_exception_noconnection(
  File "/usr/lib/python3.11/site-packages/sqlalchemy/engine/base.py", line 2198, in _handle_dbapi_exception_noconnection
    util.raise_(
  File "/usr/lib/python3.11/site-packages/sqlalchemy/util/compat.py", line 210, in raise_
    raise exception
  File "/usr/lib/python3.11/site-packages/sqlalchemy/engine/base.py", line 3361, in _wrap_pool_connect
    return fn()
           ^^^^
  File "/usr/lib/python3.11/site-packages/sqlalchemy/pool/base.py", line 325, in connect
    return _ConnectionFairy._checkout(self)
           ^^^^^^^^^^^^^^^^^^^^^^^^^^^^^^^^
  File "/usr/lib/python3.11/site-packages/sqlalchemy/pool/base.py", line 888, in _checkout
    fairy = _ConnectionRecord.checkout(pool)
            ^^^^^^^^^^^^^^^^^^^^^^^^^^^^^^^^
  File "/usr/lib/python3.11/site-packages/sqlalchemy/pool/base.py", line 491, in checkout
    rec = pool._do_get()
          ^^^^^^^^^^^^^^
  File "/usr/lib/python3.11/site-packages/sqlalchemy/pool/impl.py", line 145, in _do_get
    with util.safe_reraise():
  File "/usr/lib/python3.11/site-packages/sqlalchemy/util/langhelpers.py", line 70, in __exit__
    compat.raise_(
  File "/usr/lib/python3.11/site-packages/sqlalchemy/util/compat.py", line 210, in raise_
    raise exception
  File "/usr/lib/python3.11/site-packages/sqlalchemy/pool/impl.py", line 143, in _do_get
    return self._create_connection()
           ^^^^^^^^^^^^^^^^^^^^^^^^^
  File "/usr/lib/python3.11/site-packages/sqlalchemy/pool/base.py", line 271, in _create_connection
    return _ConnectionRecord(self)
           ^^^^^^^^^^^^^^^^^^^^^^^
  File "/usr/lib/python3.11/site-packages/sqlalchemy/pool/base.py", line 386, in __init__
    self.__connect()
  File "/usr/lib/python3.11/site-packages/sqlalchemy/pool/base.py", line 684, in __connect
    with util.safe_reraise():
  File "/usr/lib/python3.11/site-packages/sqlalchemy/util/langhelpers.py", line 70, in __exit__
    compat.raise_(
  File "/usr/lib/python3.11/site-packages/sqlalchemy/util/compat.py", line 210, in raise_
    raise exception
  File "/usr/lib/python3.11/site-packages/sqlalchemy/pool/base.py", line 680, in __connect
    self.dbapi_connection = connection = pool._invoke_creator(self)
                                         ^^^^^^^^^^^^^^^^^^^^^^^^^^
  File "/usr/lib/python3.11/site-packages/sqlalchemy/engine/create.py", line 578, in connect
    return dialect.connect(*cargs, **cparams)
           ^^^^^^^^^^^^^^^^^^^^^^^^^^^^^^^^^^
  File "/usr/lib/python3.11/site-packages/sqlalchemy/engine/default.py", line 598, in connect
    return self.dbapi.connect(*cargs, **cparams)
           ^^^^^^^^^^^^^^^^^^^^^^^^^^^^^^^^^^^^^
  File "/usr/lib/python3.11/site-packages/MySQLdb/__init__.py", line 123, in Connect
    return Connection(*args, **kwargs)
           ^^^^^^^^^^^^^^^^^^^^^^^^^^^
  File "/usr/lib/python3.11/site-packages/MySQLdb/connections.py", line 185, in __init__
    super().__init__(*args, **kwargs2)
sqlalchemy.exc.OperationalError: (MySQLdb.OperationalError) (1045, "Access denied for user 'hbnb_test'@'localhost' (using password: YES)")
(Background on this error at: https://sqlalche.me/e/14/e3q8)


======================================================================
ERROR: test_models.test_amenity (unittest.loader._FailedTest.test_models.test_amenity)
----------------------------------------------------------------------
ImportError: Failed to import test module: test_models.test_amenity
Traceback (most recent call last):
  File "/usr/lib/python3.11/site-packages/sqlalchemy/engine/base.py", line 3361, in _wrap_pool_connect
    return fn()
           ^^^^
  File "/usr/lib/python3.11/site-packages/sqlalchemy/pool/base.py", line 325, in connect
    return _ConnectionFairy._checkout(self)
           ^^^^^^^^^^^^^^^^^^^^^^^^^^^^^^^^
  File "/usr/lib/python3.11/site-packages/sqlalchemy/pool/base.py", line 888, in _checkout
    fairy = _ConnectionRecord.checkout(pool)
            ^^^^^^^^^^^^^^^^^^^^^^^^^^^^^^^^
  File "/usr/lib/python3.11/site-packages/sqlalchemy/pool/base.py", line 491, in checkout
    rec = pool._do_get()
          ^^^^^^^^^^^^^^
  File "/usr/lib/python3.11/site-packages/sqlalchemy/pool/impl.py", line 145, in _do_get
    with util.safe_reraise():
  File "/usr/lib/python3.11/site-packages/sqlalchemy/util/langhelpers.py", line 70, in __exit__
    compat.raise_(
  File "/usr/lib/python3.11/site-packages/sqlalchemy/util/compat.py", line 210, in raise_
    raise exception
  File "/usr/lib/python3.11/site-packages/sqlalchemy/pool/impl.py", line 143, in _do_get
    return self._create_connection()
           ^^^^^^^^^^^^^^^^^^^^^^^^^
  File "/usr/lib/python3.11/site-packages/sqlalchemy/pool/base.py", line 271, in _create_connection
    return _ConnectionRecord(self)
           ^^^^^^^^^^^^^^^^^^^^^^^
  File "/usr/lib/python3.11/site-packages/sqlalchemy/pool/base.py", line 386, in __init__
    self.__connect()
  File "/usr/lib/python3.11/site-packages/sqlalchemy/pool/base.py", line 684, in __connect
    with util.safe_reraise():
  File "/usr/lib/python3.11/site-packages/sqlalchemy/util/langhelpers.py", line 70, in __exit__
    compat.raise_(
  File "/usr/lib/python3.11/site-packages/sqlalchemy/util/compat.py", line 210, in raise_
    raise exception
  File "/usr/lib/python3.11/site-packages/sqlalchemy/pool/base.py", line 680, in __connect
    self.dbapi_connection = connection = pool._invoke_creator(self)
                                         ^^^^^^^^^^^^^^^^^^^^^^^^^^
  File "/usr/lib/python3.11/site-packages/sqlalchemy/engine/create.py", line 578, in connect
    return dialect.connect(*cargs, **cparams)
           ^^^^^^^^^^^^^^^^^^^^^^^^^^^^^^^^^^
  File "/usr/lib/python3.11/site-packages/sqlalchemy/engine/default.py", line 598, in connect
    return self.dbapi.connect(*cargs, **cparams)
           ^^^^^^^^^^^^^^^^^^^^^^^^^^^^^^^^^^^^^
  File "/usr/lib/python3.11/site-packages/MySQLdb/__init__.py", line 123, in Connect
    return Connection(*args, **kwargs)
           ^^^^^^^^^^^^^^^^^^^^^^^^^^^
  File "/usr/lib/python3.11/site-packages/MySQLdb/connections.py", line 185, in __init__
    super().__init__(*args, **kwargs2)
MySQLdb.OperationalError: (1045, "Access denied for user 'hbnb_test'@'localhost' (using password: YES)")

The above exception was the direct cause of the following exception:

Traceback (most recent call last):
  File "/usr/lib/python3.11/unittest/loader.py", line 419, in _find_test_path
    module = self._get_module_from_name(name)
             ^^^^^^^^^^^^^^^^^^^^^^^^^^^^^^^^
  File "/usr/lib/python3.11/unittest/loader.py", line 362, in _get_module_from_name
    __import__(name)
  File "/home/meta-bay/workspace/AirBnB_clone_v3/tests/test_models/test_amenity.py", line 8, in <module>
    import models
  File "/home/meta-bay/workspace/AirBnB_clone_v3/models/__init__.py", line 13, in <module>
    storage = DBStorage()
              ^^^^^^^^^^^
  File "/home/meta-bay/workspace/AirBnB_clone_v3/models/engine/db_storage.py", line 41, in __init__
    Base.metadata.drop_all(self.__engine)
  File "/usr/lib/python3.11/site-packages/sqlalchemy/sql/schema.py", line 4959, in drop_all
    bind._run_ddl_visitor(
  File "/usr/lib/python3.11/site-packages/sqlalchemy/engine/base.py", line 32e3q8)


======================================================================
ERROR: test_models.test_amenity (unittest.loader._FailedTest.test_models.test_amenity)
----------------------------------------------------------------------
ImportError: Failed to import test module: test_models.test_amenity
Traceback (most recent call last):
  File "/usr/lib/python3.11/site-packages/sqlalchemy/engine/base.py", line 3361, in _wrap_pool_connect
    return fn()
           ^^^^
  File "/usr/lib/python3.11/site-packages/sqlalchemy/pool/base.py", line 325, in connect
    return _ConnectionFairy._checkout(self)
           ^^^^^^^^^^^^^^^^^^^^^^^^^^^^^^^^
  File "/usr/lib/python3.11/site-packages/sqlalchemy/pool/base.py", line 888, in _checkout
    fairy = _ConnectionRecord.checkout(pool)
            ^^^^^^^^^^^^^^^^^^^^^^^^^^^^^^^^
  File "/usr/lib/python3.11/site-packages/sqlalchemy/pool/base.py", line 491, in checkout
    rec = pool._do_get()
          ^^^^^^^^^^^^^^
  File "/usr/lib/python3.11/site-packages/sqlalchemy/pool/impl.py", line 145, in _do_get
    with util.safe_reraise():
  File "/usr/lib/python3.11/site-packages/sqlalchemy/util/langhelpers.py", line 70, in __exit__
    compat.raise_(
  File "/usr/lib/python3.11/site-packages/sqlalchemy/util/compat.py", line 210, in raise_
    raise exception
  File "/usr/lib/python3.11/site-packages/sqlalchemy/pool/impl.py", line 143, in _do_get
    return self._create_connection()
           ^^^^^^^^^^^^^^^^^^^^^^^^^
  File "/usr/lib/python3.11/site-packages/sqlalchemy/pool/base.py", line 271, in _create_connection
    return _ConnectionRecord(self)
           ^^^^^^^^^^^^^^^^^^^^^^^
  File "/usr/lib/python3.11/site-packages/sqlalchemy/pool/base.py", line 386, in __init__
    self.__connect()
  File "/usr/lib/python3.11/site-packages/sqlalchemy/pool/base.py", line 684, in __connect
    with util.safe_reraise():
  File "/usr/lib/python3.11/site-packages/sqlalchemy/util/langhelpers.py", line 70, in __exit__
    compat.raise_(
  File "/usr/lib/python3.11/site-packages/sqlalchemy/util/compat.py", line 210, in raise_
    raise exception
  File "/usr/lib/python3.11/site-packages/sqlalchemy/pool/base.py", line 680, in __connect
    self.dbapi_connection = connection = pool._invoke_creator(self)
                                         ^^^^^^^^^^^^^^^^^^^^^^^^^^
  File "/usr/lib/python3.11/site-packages/sqlalchemy/engine/create.py", line 578, in connect
    return dialect.connect(*cargs, **cparams)
           ^^^^^^^^^^^^^^^^^^^^^^^^^^^^^^^^^^
  File "/usr/lib/python3.11/site-packages/sqlalchemy/engine/default.py", line 598, in connect
    return self.dbapi.connect(*cargs, **cparams)
           ^^^^^^^^^^^^^^^^^^^^^^^^^^^^^^^^^^^^^
  File "/usr/lib/python3.11/site-packages/MySQLdb/__init__.py", line 123, in Connect
    return Connection(*args, **kwargs)
           ^^^^^^^^^^^^^^^^^^^^^^^^^^^
  File "/usr/lib/python3.11/site-packages/MySQLdb/connections.py", line 185, in __init__
    super().__init__(*args, **kwargs2)
MySQLdb.OperationalError: (1045, "Access denied for user 'hbnb_test'@'localhost' (using password: YES)")

The above exception was the direct cause of the following exception:

Traceback (most recent call last):
  File "/usr/lib/python3.11/unittest/loader.py", line 419, in _find_test_path
    module = self._get_module_from_name(name)
             ^^^^^^^^^^^^^^^^^^^^^^^^^^^^^^^^
  File "/usr/lib/python3.11/unittest/loader.py", line 362, in _get_module_from_name
    __import__(name)
  File "/home/meta-bay/workspace/AirBnB_clone_v3/tests/test_models/test_amenity.py", line 8, in <module>
    import models
  File "/home/meta-bay/workspace/AirBnB_clone_v3/models/__init__.py", line 13, in <module>
    storage = DBStorage()
              ^^^^^^^^^^^
  File "/home/meta-bay/workspace/AirBnB_clone_v3/models/engine/db_storage.py", line 41, in __init__
    Base.metadata.drop_all(self.__engine)
  File "/usr/lib/python3.11/site-packages/sqlalchemy/sql/schema.py", line 4959, in drop_all
    bind._run_ddl_visitor(
  File "/usr/lib/python3.11/site-packages/sqlalchemy/engine/base.py", line 3227, in _run_ddl_visitor
    with self.begin() as conn:
         ^^^^^^^^^^^^
  File "/usr/lib/python3.11/site-packages/sqlalchemy/engine/base.py", line 3143, in begin
    conn = self.connect(close_with_result=close_with_result)
           ^^^^^^^^^^^^^^^^^^^^^^^^^^^^^^^^^^^^^^^^^^^^^^^^^
  File "/usr/lib/python3.11/site-packages/sqlalchemy/engine/base.py", line 3315, in connect
    return self._connection_cls(self, close_with_result=close_with_result)
           ^^^^^^^^^^^^^^^^^^^^^^^^^^^^^^^^^^^^^^^^^^^^^^^^^^^^^^^^^^^^^^^
  File "/usr/lib/python3.11/site-packages/sqlalchemy/engine/base.py", line 96, in __init__
    else engine.raw_connection()
         ^^^^^^^^^^^^^^^^^^^^^^^
  File "/usr/lib/python3.11/site-packages/sqlalchemy/engine/base.py", line 3394, in raw_connection
    return self._wrap_pool_connect(self.pool.connect, _connection)
           ^^^^^^^^^^^^^^^^^^^^^^^^^^^^^^^^^^^^^^^^^^^^^^^^^^^^^^^
  File "/usr/lib/python3.11/site-packages/sqlalchemy/engine/base.py", line 3364, in _wrap_pool_connect
    Connection._handle_dbapi_exception_noconnection(
  File "/usr/lib/python3.11/site-packages/sqlalchemy/engine/base.py", line 2198, in _handle_dbapi_exception_noconnection
    util.raise_(
  File "/usr/lib/python3.11/site-packages/sqlalchemy/util/compat.py", line 210, in raise_
    raise exception
  File "/usr/lib/python3.11/site-packages/sqlalchemy/engine/base.py", line 3361, in _wrap_pool_connect
    return fn()
           ^^^^
  File "/usr/lib/python3.11/site-packages/sqlalchemy/pool/base.py", line 325, in connect
    return _ConnectionFairy._checkout(self)
           ^^^^^^^^^^^^^^^^^^^^^^^^^^^^^^^^
  File "/usr/lib/python3.11/site-packages/sqlalchemy/pool/base.py", line 888, in _checkout
    fairy = _ConnectionRecord.checkout(pool)
            ^^^^^^^^^^^^^^^^^^^^^^^^^^^^^^^^
  File "/usr/lib/python3.11/site-packages/sqlalchemy/pool/base.py", line 491, in checkout
    rec = pool._do_get()
          ^^^^^^^^^^^^^^
  File "/usr/lib/python3.11/site-packages/sqlalchemy/pool/impl.py", line 145, in _do_get
    with util.safe_reraise():
  File "/usr/lib/python3.11/site-packages/sqlalchemy/util/langhelpers.py", line 70, in __exit__
    compat.raise_(
  File "/usr/lib/python3.11/site-packages/sqlalchemy/util/compat.py", line 210, in raise_
    raise exception
  File "/usr/lib/python3.11/site-packages/sqlalchemy/pool/impl.py", line 143, in _do_get
    return self._create_connection()
           ^^^^^^^^^^^^^^^^^^^^^^^^^
  File "/usr/lib/python3.11/site-packages/sqlalchemy/pool/base.py", line 271, in _create_connection
    return _ConnectionRecord(self)
           ^^^^^^^^^^^^^^^^^^^^^^^
  File "/usr/lib/python3.11/site-packages/sqlalchemy/pool/base.py", line 386, in __init__
    self.__connect()
  File "/usr/lib/python3.11/site-packages/sqlalchemy/pool/base.py", line 684, in __connect
    with util.safe_reraise():
  File "/usr/lib/python3.11/site-packages/sqlalchemy/util/langhelpers.py", line 70, in __exit__
    compat.raise_(
  File "/usr/lib/python3.11/site-packages/sqlalchemy/util/compat.py", line 210, in raise_
    raise exception
  File "/usr/lib/python3.11/site-packages/sqlalchemy/pool/base.py", line 680, in __connect
    self.dbapi_connection = connection = pool._invoke_creator(self)
                                         ^^^^^^^^^^^^^^^^^^^^^^^^^^
  File "/usr/lib/python3.11/site-packages/sqlalchemy/engine/create.py", line 578, in connect
    return dialect.connect(*cargs, **cparams)
           ^^^^^^^^^^^^^^^^^^^^^^^^^^^^^^^^^^
  File "/usr/lib/python3.11/site-packages/sqlalchemy/engine/default.py", line 598, in connect
    return self.dbapi.connect(*cargs, **cparams)
           ^^^^^^^^^^^^^^^^^^^^^^^^^^^^^^^^^^^^^
  File "/usr/lib/python3.11/site-packages/MySQLdb/__init__.py", line 123, in Connect
    return Connection(*args, **kwargs)
           ^^^^^^^^^^^^^^^^^^^^^^^^^^^
  File "/usr/lib/python3.11/site-packages/MySQLdb/connections.py", line 185, in __init__
    super().__init__(*args, **kwargs2)
sqlalchemy.exc.OperationalError: (MySQLdb.OperationalError) (1045, "Access denied for user 'hbnb_test'@'l27, in _run_ddl_visitor
    with self.begin() as conn:
         ^^^^^^^^^^^^
  File "/usr/lib/python3.11/site-packages/sqlalchemy/engine/base.py", line 3143, in begin
    conn = self.connect(close_with_result=close_with_result)
           ^^^^^^^^^^^^^^^^^^^^^^^^^^^^^^^^^^^^^^^^^^^^^^^^^
  File "/usr/lib/python3.11/site-packages/sqlalchemy/engine/base.py", line 3315, in connect
    return self._connection_cls(self, close_with_result=close_with_result)
           ^^^^^^^^^^^^^^^^^^^^^^^^^^^^^^^^^^^^^^^^^^^^^^^^^^^^^^^^^^^^^^^
  File "/usr/lib/python3.11/site-packages/sqlalchemy/engine/base.py", line 96, in __init__
    else engine.raw_connection()
         ^^^^^^^^^^^^^^^^^^^^^^^
  File "/usr/lib/python3.11/site-packages/sqlalchemy/engine/base.py", line 3394, in raw_connection
    return self._wrap_pool_connect(self.pool.connect, _connection)
           ^^^^^^^^^^^^^^^^^^^^^^^^^^^^^^^^^^^^^^^^^^^^^^^^^^^^^^^
  File "/usr/lib/python3.11/site-packages/sqlalchemy/engine/base.py", line 3364, in _wrap_pool_connect
    Connection._handle_dbapi_exception_noconnection(
  File "/usr/lib/python3.11/site-packages/sqlalchemy/engine/base.py", line 2198, in _handle_dbapi_exception_noconnection
    util.raise_(
  File "/usr/lib/python3.11/site-packages/sqlalchemy/util/compat.py", line 210, in raise_
    raise exception
  File "/usr/lib/python3.11/site-packages/sqlalchemy/engine/base.py", line 3361, in _wrap_pool_connect
    return fn()
           ^^^^
  File "/usr/lib/python3.11/site-packages/sqlalchemy/pool/base.py", line 325, in connect
    return _ConnectionFairy._checkout(self)
           ^^^^^^^^^^^^^^^^^^^^^^^^^^^^^^^^
  File "/usr/lib/python3.11/site-packages/sqlalchemy/pool/base.py", line 888, in _checkout
    fairy = _ConnectionRecord.checkout(pool)
            ^^^^^^^^^^^^^^^^^^^^^^^^^^^^^^^^
  File "/usr/lib/python3.11/site-packages/sqlalchemy/pool/base.py", line 491, in checkout
    rec = pool._do_get()
          ^^^^^^^^^^^^^^
  File "/usr/lib/python3.11/site-packages/sqlalchemy/pool/impl.py", line 145, in _do_get
    with util.safe_reraise():
  File "/usr/lib/python3.11/site-packages/sqlalchemy/util/langhelpers.py", line 70, in __exit__
    compat.raise_(
  File "/usr/lib/python3.11/site-packages/sqlalchemy/util/compat.py", line 210, in raise_
    raise exception
  File "/usr/lib/python3.11/site-packages/sqlalchemy/pool/impl.py", line 143, in _do_get
    return self._create_connection()
           ^^^^^^^^^^^^^^^^^^^^^^^^^
  File "/usr/lib/python3.11/site-packages/sqlalchemy/pool/base.py", line 271, in _create_connection
    return _ConnectionRecord(self)
           ^^^^^^^^^^^^^^^^^^^^^^^
  File "/usr/lib/python3.11/site-packages/sqlalchemy/pool/base.py", line 386, in __init__
    self.__connect()
  File "/usr/lib/python3.11/site-packages/sqlalchemy/pool/base.py", line 684, in __connect
    with util.safe_reraise():
  File "/usr/lib/python3.11/site-packages/sqlalchemy/util/langhelpers.py", line 70, in __exit__
    compat.raise_(
  File "/usr/lib/python3.11/site-packages/sqlalchemy/util/compat.py", line 210, in raise_
    raise exception
  File "/usr/lib/python3.11/site-packages/sqlalchemy/pool/base.py", line 680, in __connect
    self.dbapi_connection = connection = pool._invoke_creator(self)
                                         ^^^^^^^^^^^^^^^^^^^^^^^^^^
  File "/usr/lib/python3.11/site-packages/sqlalchemy/engine/create.py", line 578, in connect
    return dialect.connect(*cargs, **cparams)
           ^^^^^^^^^^^^^^^^^^^^^^^^^^^^^^^^^^
  File "/usr/lib/python3.11/site-packages/sqlalchemy/engine/default.py", line 598, in connect
    return self.dbapi.connect(*cargs, **cparams)
           ^^^^^^^^^^^^^^^^^^^^^^^^^^^^^^^^^^^^^
  File "/usr/lib/python3.11/site-packages/MySQLdb/__init__.py", line 123, in Connect
    return Connection(*args, **kwargs)
           ^^^^^^^^^^^^^^^^^^^^^^^^^^^
  File "/usr/lib/python3.11/site-packages/MySQLdb/connections.py", line 185, in __init__
    super().__init__(*args, **kwargs2)
sqlalchemy.exc.OperationalError: (MySQLdb.OperationalError) (1045, "Access denied for user 'hbnb_test'@'localhost' (using password: YES)")
(Background on this error at: https://sqlalche.me/e/14/e3q8)


======================================================================
ERROR: test_models.test_base_model (unittest.loader._FailedTest.test_models.test_base_model)
----------------------------------------------------------------------
ImportError: Failed to import test module: test_models.test_base_model
Traceback (most recent call last):
  File "/usr/lib/python3.11/site-packages/sqlalchemy/engine/base.py", line 3361, in _wrap_pool_connect
    return fn()
           ^^^^
  File "/usr/lib/python3.11/site-packages/sqlalchemy/pool/base.py", line 325, in connect
    return _ConnectionFairy._checkout(self)
           ^^^^^^^^^^^^^^^^^^^^^^^^^^^^^^^^
  File "/usr/lib/python3.11/site-packages/sqlalchemy/pool/base.py", line 888, in _checkout
    fairy = _ConnectionRecord.checkout(pool)
            ^^^^^^^^^^^^^^^^^^^^^^^^^^^^^^^^
  File "/usr/lib/python3.11/site-packages/sqlalchemy/pool/base.py", line 491, in checkout
    rec = pool._do_get()
          ^^^^^^^^^^^^^^
  File "/usr/lib/python3.11/site-packages/sqlalchemy/pool/impl.py", line 145, in _do_get
    with util.safe_reraise():
  File "/usr/lib/python3.11/site-packages/sqlalchemy/util/langhelpers.py", line 70, in __exit__
    compat.raise_(
  File "/usr/lib/python3.11/site-packages/sqlalchemy/util/compat.py", line 210, in raise_
    raise exception
  File "/usr/lib/python3.11/site-packages/sqlalchemy/pool/impl.py", line 143, in _do_get
    return self._create_connection()
           ^^^^^^^^^^^^^^^^^^^^^^^^^
  File "/usr/lib/python3.11/site-packages/sqlalchemy/pool/base.py", line 271, in _create_connection
    return _ConnectionRecord(self)
           ^^^^^^^^^^^^^^^^^^^^^^^
  File "/usr/lib/python3.11/site-packages/sqlalchemy/pool/base.py", line 386, in __init__
    self.__connect()
  File "/usr/lib/python3.11/site-packages/sqlalchemy/pool/base.py", line 684, in __connect
    with util.safe_reraise():
  File "/usr/lib/python3.11/site-packages/sqlalchemy/util/langhelpers.py", line 70, in __exit__
    compat.raise_(
  File "/usr/lib/python3.11/site-packages/sqlalchemy/util/compat.py", line 210, in raise_
    raise exception
  File "/usr/lib/python3.11/site-packages/sqlalchemy/pool/base.py", line 680, in __connect
    self.dbapi_connection = connection = pool._invoke_creator(self)
                                         ^^^^^^^^^^^^^^^^^^^^^^^^^^
  File "/usr/lib/python3.11/site-packages/sqlalchemy/engine/create.py", line 578, in connect
    return dialect.connect(*cargs, **cparams)
           ^^^^^^^^^^^^^^^^^^^^^^^^^^^^^^^^^^
  File "/usr/lib/python3.11/site-packages/sqlalchemy/engine/default.py", line 598, in connect
    return self.dbapi.connect(*cargs, **cparams)
           ^^^^^^^^^^^^^^^^^^^^^^^^^^^^^^^^^^^^^
  File "/usr/lib/python3.11/site-packages/MySQLdb/__init__.py", line 123, in Connect
    return Connection(*args, **kwargs)
           ^^^^^^^^^^^^^^^^^^^^^^^^^^^
  File "/usr/lib/python3.11/site-packages/MySQLdb/connections.py", line 185, in __init__
    super().__init__(*args, **kwargs2)
MySQLdb.OperationalError: (1045, "Access denied for user 'hbnb_test'@'localhost' (using password: YES)")

The above exception was the direct cause of the following exception:

Traceback (most recent call last):
  File "/usr/lib/python3.11/unittest/loader.py", line 419, in _find_test_path
    module = self._get_module_from_name(name)
             ^^^^^^^^^^^^^^^^^^^^^^^^^^^^^^^^
  File "/usr/lib/python3.11/unittest/loader.py", line 362, in _get_module_from_name
    __import__(name)
  File "/home/meta-bay/workspace/AirBnB_clone_v3/tests/test_models/test_base_model.py", line 5, in <module>
    import models
  File "/home/meta-bay/workspace/AirBnB_clone_v3/models/__init__.py", line 13, in <module>
    storage = DBStorage()
              ^^^^^^^^^^^
  File "/home/meta-bay/workspace/AirBnB_clone_v3/models/engine/db_storage.py", line 41, in __init__
    Base.metadata.drop_all(self.__engine)
  File "/usr/lib/python3.11/site-packages/sqlalchemy/sql/schema.py", line 4959, in drop_all
   ocalhost' (using password: YES)")
(Background on this error at: https://sqlalche.me/e/14/e3q8)


======================================================================
ERROR: test_models.test_base_model (unittest.loader._FailedTest.test_models.test_base_model)
----------------------------------------------------------------------
ImportError: Failed to import test module: test_models.test_base_model
Traceback (most recent call last):
  File "/usr/lib/python3.11/site-packages/sqlalchemy/engine/base.py", line 3361, in _wrap_pool_connect
    return fn()
           ^^^^
  File "/usr/lib/python3.11/site-packages/sqlalchemy/pool/base.py", line 325, in connect
    return _ConnectionFairy._checkout(self)
           ^^^^^^^^^^^^^^^^^^^^^^^^^^^^^^^^
  File "/usr/lib/python3.11/site-packages/sqlalchemy/pool/base.py", line 888, in _checkout
    fairy = _ConnectionRecord.checkout(pool)
            ^^^^^^^^^^^^^^^^^^^^^^^^^^^^^^^^
  File "/usr/lib/python3.11/site-packages/sqlalchemy/pool/base.py", line 491, in checkout
    rec = pool._do_get()
          ^^^^^^^^^^^^^^
  File "/usr/lib/python3.11/site-packages/sqlalchemy/pool/impl.py", line 145, in _do_get
    with util.safe_reraise():
  File "/usr/lib/python3.11/site-packages/sqlalchemy/util/langhelpers.py", line 70, in __exit__
    compat.raise_(
  File "/usr/lib/python3.11/site-packages/sqlalchemy/util/compat.py", line 210, in raise_
    raise exception
  File "/usr/lib/python3.11/site-packages/sqlalchemy/pool/impl.py", line 143, in _do_get
    return self._create_connection()
           ^^^^^^^^^^^^^^^^^^^^^^^^^
  File "/usr/lib/python3.11/site-packages/sqlalchemy/pool/base.py", line 271, in _create_connection
    return _ConnectionRecord(self)
           ^^^^^^^^^^^^^^^^^^^^^^^
  File "/usr/lib/python3.11/site-packages/sqlalchemy/pool/base.py", line 386, in __init__
    self.__connect()
  File "/usr/lib/python3.11/site-packages/sqlalchemy/pool/base.py", line 684, in __connect
    with util.safe_reraise():
  File "/usr/lib/python3.11/site-packages/sqlalchemy/util/langhelpers.py", line 70, in __exit__
    compat.raise_(
  File "/usr/lib/python3.11/site-packages/sqlalchemy/util/compat.py", line 210, in raise_
    raise exception
  File "/usr/lib/python3.11/site-packages/sqlalchemy/pool/base.py", line 680, in __connect
    self.dbapi_connection = connection = pool._invoke_creator(self)
                                         ^^^^^^^^^^^^^^^^^^^^^^^^^^
  File "/usr/lib/python3.11/site-packages/sqlalchemy/engine/create.py", line 578, in connect
    return dialect.connect(*cargs, **cparams)
           ^^^^^^^^^^^^^^^^^^^^^^^^^^^^^^^^^^
  File "/usr/lib/python3.11/site-packages/sqlalchemy/engine/default.py", line 598, in connect
    return self.dbapi.connect(*cargs, **cparams)
           ^^^^^^^^^^^^^^^^^^^^^^^^^^^^^^^^^^^^^
  File "/usr/lib/python3.11/site-packages/MySQLdb/__init__.py", line 123, in Connect
    return Connection(*args, **kwargs)
           ^^^^^^^^^^^^^^^^^^^^^^^^^^^
  File "/usr/lib/python3.11/site-packages/MySQLdb/connections.py", line 185, in __init__
    super().__init__(*args, **kwargs2)
MySQLdb.OperationalError: (1045, "Access denied for user 'hbnb_test'@'localhost' (using password: YES)")

The above exception was the direct cause of the following exception:

Traceback (most recent call last):
  File "/usr/lib/python3.11/unittest/loader.py", line 419, in _find_test_path
    module = self._get_module_from_name(name)
             ^^^^^^^^^^^^^^^^^^^^^^^^^^^^^^^^
  File "/usr/lib/python3.11/unittest/loader.py", line 362, in _get_module_from_name
    __import__(name)
  File "/home/meta-bay/workspace/AirBnB_clone_v3/tests/test_models/test_base_model.py", line 5, in <module>
    import models
  File "/home/meta-bay/workspace/AirBnB_clone_v3/models/__init__.py", line 13, in <module>
    storage = DBStorage()
              ^^^^^^^^^^^
  File "/home/meta-bay/workspace/AirBnB_clone_v3/models/engine/db_storage.py", line 41, in __init__
    Base.metadata.drop_all(self.__engine)
  File "/usr/lib/python3.11/site-packages/sqlalchemy/sql/schema.py", line 4959, in drop_all
    bind._run_ddl_visitor(
  File "/usr/lib/python3.11/site-packages/sqlalchemy/engine/base.py", line 3227, in _run_ddl_visitor
    with self.begin() as conn:
         ^^^^^^^^^^^^
  File "/usr/lib/python3.11/site-packages/sqlalchemy/engine/base.py", line 3143, in begin
    conn = self.connect(close_with_result=close_with_result)
           ^^^^^^^^^^^^^^^^^^^^^^^^^^^^^^^^^^^^^^^^^^^^^^^^^
  File "/usr/lib/python3.11/site-packages/sqlalchemy/engine/base.py", line 3315, in connect
    return self._connection_cls(self, close_with_result=close_with_result)
           ^^^^^^^^^^^^^^^^^^^^^^^^^^^^^^^^^^^^^^^^^^^^^^^^^^^^^^^^^^^^^^^
  File "/usr/lib/python3.11/site-packages/sqlalchemy/engine/base.py", line 96, in __init__
    else engine.raw_connection()
         ^^^^^^^^^^^^^^^^^^^^^^^
  File "/usr/lib/python3.11/site-packages/sqlalchemy/engine/base.py", line 3394, in raw_connection
    return self._wrap_pool_connect(self.pool.connect, _connection)
           ^^^^^^^^^^^^^^^^^^^^^^^^^^^^^^^^^^^^^^^^^^^^^^^^^^^^^^^
  File "/usr/lib/python3.11/site-packages/sqlalchemy/engine/base.py", line 3364, in _wrap_pool_connect
    Connection._handle_dbapi_exception_noconnection(
  File "/usr/lib/python3.11/site-packages/sqlalchemy/engine/base.py", line 2198, in _handle_dbapi_exception_noconnection
    util.raise_(
  File "/usr/lib/python3.11/site-packages/sqlalchemy/util/compat.py", line 210, in raise_
    raise exception
  File "/usr/lib/python3.11/site-packages/sqlalchemy/engine/base.py", line 3361, in _wrap_pool_connect
    return fn()
           ^^^^
  File "/usr/lib/python3.11/site-packages/sqlalchemy/pool/base.py", line 325, in connect
    return _ConnectionFairy._checkout(self)
           ^^^^^^^^^^^^^^^^^^^^^^^^^^^^^^^^
  File "/usr/lib/python3.11/site-packages/sqlalchemy/pool/base.py", line 888, in _checkout
    fairy = _ConnectionRecord.checkout(pool)
            ^^^^^^^^^^^^^^^^^^^^^^^^^^^^^^^^
  File "/usr/lib/python3.11/site-packages/sqlalchemy/pool/base.py", line 491, in checkout
    rec = pool._do_get()
          ^^^^^^^^^^^^^^
  File "/usr/lib/python3.11/site-packages/sqlalchemy/pool/impl.py", line 145, in _do_get
    with util.safe_reraise():
  File "/usr/lib/python3.11/site-packages/sqlalchemy/util/langhelpers.py", line 70, in __exit__
    compat.raise_(
  File "/usr/lib/python3.11/site-packages/sqlalchemy/util/compat.py", line 210, in raise_
    raise exception
  File "/usr/lib/python3.11/site-packages/sqlalchemy/pool/impl.py", line 143, in _do_get
    return self._create_connection()
           ^^^^^^^^^^^^^^^^^^^^^^^^^
  File "/usr/lib/python3.11/site-packages/sqlalchemy/pool/base.py", line 271, in _create_connection
    return _ConnectionRecord(self)
           ^^^^^^^^^^^^^^^^^^^^^^^
  File "/usr/lib/python3.11/site-packages/sqlalchemy/pool/base.py", line 386, in __init__
    self.__connect()
  File "/usr/lib/python3.11/site-packages/sqlalchemy/pool/base.py", line 684, in __connect
    with util.safe_reraise():
  File "/usr/lib/python3.11/site-packages/sqlalchemy/util/langhelpers.py", line 70, in __exit__
    compat.raise_(
  File "/usr/lib/python3.11/site-packages/sqlalchemy/util/compat.py", line 210, in raise_
    raise exception
  File "/usr/lib/python3.11/site-packages/sqlalchemy/pool/base.py", line 680, in __connect
    self.dbapi_connection = connection = pool._invoke_creator(self)
                                         ^^^^^^^^^^^^^^^^^^^^^^^^^^
  File "/usr/lib/python3.11/site-packages/sqlalchemy/engine/create.py", line 578, in connect
    return dialect.connect(*cargs, **cparams)
           ^^^^^^^^^^^^^^^^^^^^^^^^^^^^^^^^^^
  File "/usr/lib/python3.11/site-packages/sqlalchemy/engine/default.py", line 598, in connect
    return self.dbapi.connect(*cargs, **cparams)
           ^^^^^^^^^^^^^^^^^^^^^^^^^^^^^^^^^^^^^
  File "/usr/lib/python3.11/site-packages/MySQLdb/__init__.py", line 123, in Connect
    return Connection(*args, **kwargs)
           ^^^^^^^^^^^^^^^^^^^^^^^^^^^
  File "/usr/lib/python3.11/site-packages/MySQLdb/connections.py", line 185, in __init__
    super().__init__(*args, **kwargs2)
sqla bind._run_ddl_visitor(
  File "/usr/lib/python3.11/site-packages/sqlalchemy/engine/base.py", line 3227, in _run_ddl_visitor
    with self.begin() as conn:
         ^^^^^^^^^^^^
  File "/usr/lib/python3.11/site-packages/sqlalchemy/engine/base.py", line 3143, in begin
    conn = self.connect(close_with_result=close_with_result)
           ^^^^^^^^^^^^^^^^^^^^^^^^^^^^^^^^^^^^^^^^^^^^^^^^^
  File "/usr/lib/python3.11/site-packages/sqlalchemy/engine/base.py", line 3315, in connect
    return self._connection_cls(self, close_with_result=close_with_result)
           ^^^^^^^^^^^^^^^^^^^^^^^^^^^^^^^^^^^^^^^^^^^^^^^^^^^^^^^^^^^^^^^
  File "/usr/lib/python3.11/site-packages/sqlalchemy/engine/base.py", line 96, in __init__
    else engine.raw_connection()
         ^^^^^^^^^^^^^^^^^^^^^^^
  File "/usr/lib/python3.11/site-packages/sqlalchemy/engine/base.py", line 3394, in raw_connection
    return self._wrap_pool_connect(self.pool.connect, _connection)
           ^^^^^^^^^^^^^^^^^^^^^^^^^^^^^^^^^^^^^^^^^^^^^^^^^^^^^^^
  File "/usr/lib/python3.11/site-packages/sqlalchemy/engine/base.py", line 3364, in _wrap_pool_connect
    Connection._handle_dbapi_exception_noconnection(
  File "/usr/lib/python3.11/site-packages/sqlalchemy/engine/base.py", line 2198, in _handle_dbapi_exception_noconnection
    util.raise_(
  File "/usr/lib/python3.11/site-packages/sqlalchemy/util/compat.py", line 210, in raise_
    raise exception
  File "/usr/lib/python3.11/site-packages/sqlalchemy/engine/base.py", line 3361, in _wrap_pool_connect
    return fn()
           ^^^^
  File "/usr/lib/python3.11/site-packages/sqlalchemy/pool/base.py", line 325, in connect
    return _ConnectionFairy._checkout(self)
           ^^^^^^^^^^^^^^^^^^^^^^^^^^^^^^^^
  File "/usr/lib/python3.11/site-packages/sqlalchemy/pool/base.py", line 888, in _checkout
    fairy = _ConnectionRecord.checkout(pool)
            ^^^^^^^^^^^^^^^^^^^^^^^^^^^^^^^^
  File "/usr/lib/python3.11/site-packages/sqlalchemy/pool/base.py", line 491, in checkout
    rec = pool._do_get()
          ^^^^^^^^^^^^^^
  File "/usr/lib/python3.11/site-packages/sqlalchemy/pool/impl.py", line 145, in _do_get
    with util.safe_reraise():
  File "/usr/lib/python3.11/site-packages/sqlalchemy/util/langhelpers.py", line 70, in __exit__
    compat.raise_(
  File "/usr/lib/python3.11/site-packages/sqlalchemy/util/compat.py", line 210, in raise_
    raise exception
  File "/usr/lib/python3.11/site-packages/sqlalchemy/pool/impl.py", line 143, in _do_get
    return self._create_connection()
           ^^^^^^^^^^^^^^^^^^^^^^^^^
  File "/usr/lib/python3.11/site-packages/sqlalchemy/pool/base.py", line 271, in _create_connection
    return _ConnectionRecord(self)
           ^^^^^^^^^^^^^^^^^^^^^^^
  File "/usr/lib/python3.11/site-packages/sqlalchemy/pool/base.py", line 386, in __init__
    self.__connect()
  File "/usr/lib/python3.11/site-packages/sqlalchemy/pool/base.py", line 684, in __connect
    with util.safe_reraise():
  File "/usr/lib/python3.11/site-packages/sqlalchemy/util/langhelpers.py", line 70, in __exit__
    compat.raise_(
  File "/usr/lib/python3.11/site-packages/sqlalchemy/util/compat.py", line 210, in raise_
    raise exception
  File "/usr/lib/python3.11/site-packages/sqlalchemy/pool/base.py", line 680, in __connect
    self.dbapi_connection = connection = pool._invoke_creator(self)
                                         ^^^^^^^^^^^^^^^^^^^^^^^^^^
  File "/usr/lib/python3.11/site-packages/sqlalchemy/engine/create.py", line 578, in connect
    return dialect.connect(*cargs, **cparams)
           ^^^^^^^^^^^^^^^^^^^^^^^^^^^^^^^^^^
  File "/usr/lib/python3.11/site-packages/sqlalchemy/engine/default.py", line 598, in connect
    return self.dbapi.connect(*cargs, **cparams)
           ^^^^^^^^^^^^^^^^^^^^^^^^^^^^^^^^^^^^^
  File "/usr/lib/python3.11/site-packages/MySQLdb/__init__.py", line 123, in Connect
    return Connection(*args, **kwargs)
           ^^^^^^^^^^^^^^^^^^^^^^^^^^^
  File "/usr/lib/python3.11/site-packages/MySQLdb/connections.py", line 185, in __init__
    super().__init__(*args, **kwargs2)
sqlalchemy.exc.OperationalError: (MySQLdb.OperationalError) (1045, "Access denied for user 'hbnb_test'@'localhost' (using password: YES)")
(Background on this error at: https://sqlalche.me/e/14/e3q8)


======================================================================
ERROR: test_models.test_city (unittest.loader._FailedTest.test_models.test_city)
----------------------------------------------------------------------
ImportError: Failed to import test module: test_models.test_city
Traceback (most recent call last):
  File "/usr/lib/python3.11/site-packages/sqlalchemy/engine/base.py", line 3361, in _wrap_pool_connect
    return fn()
           ^^^^
  File "/usr/lib/python3.11/site-packages/sqlalchemy/pool/base.py", line 325, in connect
    return _ConnectionFairy._checkout(self)
           ^^^^^^^^^^^^^^^^^^^^^^^^^^^^^^^^
  File "/usr/lib/python3.11/site-packages/sqlalchemy/pool/base.py", line 888, in _checkout
    fairy = _ConnectionRecord.checkout(pool)
            ^^^^^^^^^^^^^^^^^^^^^^^^^^^^^^^^
  File "/usr/lib/python3.11/site-packages/sqlalchemy/pool/base.py", line 491, in checkout
    rec = pool._do_get()
          ^^^^^^^^^^^^^^
  File "/usr/lib/python3.11/site-packages/sqlalchemy/pool/impl.py", line 145, in _do_get
    with util.safe_reraise():
  File "/usr/lib/python3.11/site-packages/sqlalchemy/util/langhelpers.py", line 70, in __exit__
    compat.raise_(
  File "/usr/lib/python3.11/site-packages/sqlalchemy/util/compat.py", line 210, in raise_
    raise exception
  File "/usr/lib/python3.11/site-packages/sqlalchemy/pool/impl.py", line 143, in _do_get
    return self._create_connection()
           ^^^^^^^^^^^^^^^^^^^^^^^^^
  File "/usr/lib/python3.11/site-packages/sqlalchemy/pool/base.py", line 271, in _create_connection
    return _ConnectionRecord(self)
           ^^^^^^^^^^^^^^^^^^^^^^^
  File "/usr/lib/python3.11/site-packages/sqlalchemy/pool/base.py", line 386, in __init__
    self.__connect()
  File "/usr/lib/python3.11/site-packages/sqlalchemy/pool/base.py", line 684, in __connect
    with util.safe_reraise():
  File "/usr/lib/python3.11/site-packages/sqlalchemy/util/langhelpers.py", line 70, in __exit__
    compat.raise_(
  File "/usr/lib/python3.11/site-packages/sqlalchemy/util/compat.py", line 210, in raise_
    raise exception
  File "/usr/lib/python3.11/site-packages/sqlalchemy/pool/base.py", line 680, in __connect
    self.dbapi_connection = connection = pool._invoke_creator(self)
                                         ^^^^^^^^^^^^^^^^^^^^^^^^^^
  File "/usr/lib/python3.11/site-packages/sqlalchemy/engine/create.py", line 578, in connect
    return dialect.connect(*cargs, **cparams)
           ^^^^^^^^^^^^^^^^^^^^^^^^^^^^^^^^^^
  File "/usr/lib/python3.11/site-packages/sqlalchemy/engine/default.py", line 598, in connect
    return self.dbapi.connect(*cargs, **cparams)
           ^^^^^^^^^^^^^^^^^^^^^^^^^^^^^^^^^^^^^
  File "/usr/lib/python3.11/site-packages/MySQLdb/__init__.py", line 123, in Connect
    return Connection(*args, **kwargs)
           ^^^^^^^^^^^^^^^^^^^^^^^^^^^
  File "/usr/lib/python3.11/site-packages/MySQLdb/connections.py", line 185, in __init__
    super().__init__(*args, **kwargs2)
MySQLdb.OperationalError: (1045, "Access denied for user 'hbnb_test'@'localhost' (using password: YES)")

The above exception was the direct cause of the following exception:

Traceback (most recent call last):
  File "/usr/lib/python3.11/unittest/loader.py", line 419, in _find_test_path
    module = self._get_module_from_name(name)
             ^^^^^^^^^^^^^^^^^^^^^^^^^^^^^^^^
  File "/usr/lib/python3.11/unittest/loader.py", line 362, in _get_module_from_name
    __import__(name)
  File "/home/meta-bay/workspace/AirBnB_clone_v3/tests/test_models/test_city.py", line 8, in <module>
    import models
  File "/home/meta-bay/workspace/AirBnB_clone_v3/models/__init__.py", line 13, in <module>
    storage = DBStorage()
              ^^^^^^^^^^^
  File "/home/meta-bay/workspace/AirBnB_clone_v3/models/engine/db_storage.py", line 41, in __init__
    Base.metadata.drop_all(self.__engine)
  File "/usr/lib/plchemy.exc.OperationalError: (MySQLdb.OperationalError) (1045, "Access denied for user 'hbnb_test'@'localhost' (using password: YES)")
(Background on this error at: https://sqlalche.me/e/14/e3q8)


======================================================================
ERROR: test_models.test_city (unittest.loader._FailedTest.test_models.test_city)
----------------------------------------------------------------------
ImportError: Failed to import test module: test_models.test_city
Traceback (most recent call last):
  File "/usr/lib/python3.11/site-packages/sqlalchemy/engine/base.py", line 3361, in _wrap_pool_connect
    return fn()
           ^^^^
  File "/usr/lib/python3.11/site-packages/sqlalchemy/pool/base.py", line 325, in connect
    return _ConnectionFairy._checkout(self)
           ^^^^^^^^^^^^^^^^^^^^^^^^^^^^^^^^
  File "/usr/lib/python3.11/site-packages/sqlalchemy/pool/base.py", line 888, in _checkout
    fairy = _ConnectionRecord.checkout(pool)
            ^^^^^^^^^^^^^^^^^^^^^^^^^^^^^^^^
  File "/usr/lib/python3.11/site-packages/sqlalchemy/pool/base.py", line 491, in checkout
    rec = pool._do_get()
          ^^^^^^^^^^^^^^
  File "/usr/lib/python3.11/site-packages/sqlalchemy/pool/impl.py", line 145, in _do_get
    with util.safe_reraise():
  File "/usr/lib/python3.11/site-packages/sqlalchemy/util/langhelpers.py", line 70, in __exit__
    compat.raise_(
  File "/usr/lib/python3.11/site-packages/sqlalchemy/util/compat.py", line 210, in raise_
    raise exception
  File "/usr/lib/python3.11/site-packages/sqlalchemy/pool/impl.py", line 143, in _do_get
    return self._create_connection()
           ^^^^^^^^^^^^^^^^^^^^^^^^^
  File "/usr/lib/python3.11/site-packages/sqlalchemy/pool/base.py", line 271, in _create_connection
    return _ConnectionRecord(self)
           ^^^^^^^^^^^^^^^^^^^^^^^
  File "/usr/lib/python3.11/site-packages/sqlalchemy/pool/base.py", line 386, in __init__
    self.__connect()
  File "/usr/lib/python3.11/site-packages/sqlalchemy/pool/base.py", line 684, in __connect
    with util.safe_reraise():
  File "/usr/lib/python3.11/site-packages/sqlalchemy/util/langhelpers.py", line 70, in __exit__
    compat.raise_(
  File "/usr/lib/python3.11/site-packages/sqlalchemy/util/compat.py", line 210, in raise_
    raise exception
  File "/usr/lib/python3.11/site-packages/sqlalchemy/pool/base.py", line 680, in __connect
    self.dbapi_connection = connection = pool._invoke_creator(self)
                                         ^^^^^^^^^^^^^^^^^^^^^^^^^^
  File "/usr/lib/python3.11/site-packages/sqlalchemy/engine/create.py", line 578, in connect
    return dialect.connect(*cargs, **cparams)
           ^^^^^^^^^^^^^^^^^^^^^^^^^^^^^^^^^^
  File "/usr/lib/python3.11/site-packages/sqlalchemy/engine/default.py", line 598, in connect
    return self.dbapi.connect(*cargs, **cparams)
           ^^^^^^^^^^^^^^^^^^^^^^^^^^^^^^^^^^^^^
  File "/usr/lib/python3.11/site-packages/MySQLdb/__init__.py", line 123, in Connect
    return Connection(*args, **kwargs)
           ^^^^^^^^^^^^^^^^^^^^^^^^^^^
  File "/usr/lib/python3.11/site-packages/MySQLdb/connections.py", line 185, in __init__
    super().__init__(*args, **kwargs2)
MySQLdb.OperationalError: (1045, "Access denied for user 'hbnb_test'@'localhost' (using password: YES)")

The above exception was the direct cause of the following exception:

Traceback (most recent call last):
  File "/usr/lib/python3.11/unittest/loader.py", line 419, in _find_test_path
    module = self._get_module_from_name(name)
             ^^^^^^^^^^^^^^^^^^^^^^^^^^^^^^^^
  File "/usr/lib/python3.11/unittest/loader.py", line 362, in _get_module_from_name
    __import__(name)
  File "/home/meta-bay/workspace/AirBnB_clone_v3/tests/test_models/test_city.py", line 8, in <module>
    import models
  File "/home/meta-bay/workspace/AirBnB_clone_v3/models/__init__.py", line 13, in <module>
    storage = DBStorage()
              ^^^^^^^^^^^
  File "/home/meta-bay/workspace/AirBnB_clone_v3/models/engine/db_storage.py", line 41, in __init__
    Base.metadata.drop_all(self.__engine)
  File "/usr/lib/python3.11/site-packages/sqlalchemy/sql/schema.py", line 4959, in drop_all
    bind._run_ddl_visitor(
  File "/usr/lib/python3.11/site-packages/sqlalchemy/engine/base.py", line 3227, in _run_ddl_visitor
    with self.begin() as conn:
         ^^^^^^^^^^^^
  File "/usr/lib/python3.11/site-packages/sqlalchemy/engine/base.py", line 3143, in begin
    conn = self.connect(close_with_result=close_with_result)
           ^^^^^^^^^^^^^^^^^^^^^^^^^^^^^^^^^^^^^^^^^^^^^^^^^
  File "/usr/lib/python3.11/site-packages/sqlalchemy/engine/base.py", line 3315, in connect
    return self._connection_cls(self, close_with_result=close_with_result)
           ^^^^^^^^^^^^^^^^^^^^^^^^^^^^^^^^^^^^^^^^^^^^^^^^^^^^^^^^^^^^^^^
  File "/usr/lib/python3.11/site-packages/sqlalchemy/engine/base.py", line 96, in __init__
    else engine.raw_connection()
         ^^^^^^^^^^^^^^^^^^^^^^^
  File "/usr/lib/python3.11/site-packages/sqlalchemy/engine/base.py", line 3394, in raw_connection
    return self._wrap_pool_connect(self.pool.connect, _connection)
           ^^^^^^^^^^^^^^^^^^^^^^^^^^^^^^^^^^^^^^^^^^^^^^^^^^^^^^^
  File "/usr/lib/python3.11/site-packages/sqlalchemy/engine/base.py", line 3364, in _wrap_pool_connect
    Connection._handle_dbapi_exception_noconnection(
  File "/usr/lib/python3.11/site-packages/sqlalchemy/engine/base.py", line 2198, in _handle_dbapi_exception_noconnection
    util.raise_(
  File "/usr/lib/python3.11/site-packages/sqlalchemy/util/compat.py", line 210, in raise_
    raise exception
  File "/usr/lib/python3.11/site-packages/sqlalchemy/engine/base.py", line 3361, in _wrap_pool_connect
    return fn()
           ^^^^
  File "/usr/lib/python3.11/site-packages/sqlalchemy/pool/base.py", line 325, in connect
    return _ConnectionFairy._checkout(self)
           ^^^^^^^^^^^^^^^^^^^^^^^^^^^^^^^^
  File "/usr/lib/python3.11/site-packages/sqlalchemy/pool/base.py", line 888, in _checkout
    fairy = _ConnectionRecord.checkout(pool)
            ^^^^^^^^^^^^^^^^^^^^^^^^^^^^^^^^
  File "/usr/lib/python3.11/site-packages/sqlalchemy/pool/base.py", line 491, in checkout
    rec = pool._do_get()
          ^^^^^^^^^^^^^^
  File "/usr/lib/python3.11/site-packages/sqlalchemy/pool/impl.py", line 145, in _do_get
    with util.safe_reraise():
  File "/usr/lib/python3.11/site-packages/sqlalchemy/util/langhelpers.py", line 70, in __exit__
    compat.raise_(
  File "/usr/lib/python3.11/site-packages/sqlalchemy/util/compat.py", line 210, in raise_
    raise exception
  File "/usr/lib/python3.11/site-packages/sqlalchemy/pool/impl.py", line 143, in _do_get
    return self._create_connection()
           ^^^^^^^^^^^^^^^^^^^^^^^^^
  File "/usr/lib/python3.11/site-packages/sqlalchemy/pool/base.py", line 271, in _create_connection
    return _ConnectionRecord(self)
           ^^^^^^^^^^^^^^^^^^^^^^^
  File "/usr/lib/python3.11/site-packages/sqlalchemy/pool/base.py", line 386, in __init__
    self.__connect()
  File "/usr/lib/python3.11/site-packages/sqlalchemy/pool/base.py", line 684, in __connect
    with util.safe_reraise():
  File "/usr/lib/python3.11/site-packages/sqlalchemy/util/langhelpers.py", line 70, in __exit__
    compat.raise_(
  File "/usr/lib/python3.11/site-packages/sqlalchemy/util/compat.py", line 210, in raise_
    raise exception
  File "/usr/lib/python3.11/site-packages/sqlalchemy/pool/base.py", line 680, in __connect
    self.dbapi_connection = connection = pool._invoke_creator(self)
                                         ^^^^^^^^^^^^^^^^^^^^^^^^^^
  File "/usr/lib/python3.11/site-packages/sqlalchemy/engine/create.py", line 578, in connect
    return dialect.connect(*cargs, **cparams)
           ^^^^^^^^^^^^^^^^^^^^^^^^^^^^^^^^^^
  File "/usr/lib/python3.11/site-packages/sqlalchemy/engine/default.py", line 598, in connect
    return self.dbapi.connect(*cargs, **cparams)
           ^^^^^^^^^^^^^^^^^^^^^^^^^^^^^^^^^^^^^
  File "/usr/lib/python3.11/site-packages/MySQLdb/__init__.py", line 123, in Connect
    return Connection(*args, **kwargs)
           ^^^^^^^^^^^^^^^^^^^^^^^^^^^
  File "/usr/lib/python3.11/site-packages/MySQLdb/conneython3.11/site-packages/sqlalchemy/sql/schema.py", line 4959, in drop_all
    bind._run_ddl_visitor(
  File "/usr/lib/python3.11/site-packages/sqlalchemy/engine/base.py", line 3227, in _run_ddl_visitor
    with self.begin() as conn:
         ^^^^^^^^^^^^
  File "/usr/lib/python3.11/site-packages/sqlalchemy/engine/base.py", line 3143, in begin
    conn = self.connect(close_with_result=close_with_result)
           ^^^^^^^^^^^^^^^^^^^^^^^^^^^^^^^^^^^^^^^^^^^^^^^^^
  File "/usr/lib/python3.11/site-packages/sqlalchemy/engine/base.py", line 3315, in connect
    return self._connection_cls(self, close_with_result=close_with_result)
           ^^^^^^^^^^^^^^^^^^^^^^^^^^^^^^^^^^^^^^^^^^^^^^^^^^^^^^^^^^^^^^^
  File "/usr/lib/python3.11/site-packages/sqlalchemy/engine/base.py", line 96, in __init__
    else engine.raw_connection()
         ^^^^^^^^^^^^^^^^^^^^^^^
  File "/usr/lib/python3.11/site-packages/sqlalchemy/engine/base.py", line 3394, in raw_connection
    return self._wrap_pool_connect(self.pool.connect, _connection)
           ^^^^^^^^^^^^^^^^^^^^^^^^^^^^^^^^^^^^^^^^^^^^^^^^^^^^^^^
  File "/usr/lib/python3.11/site-packages/sqlalchemy/engine/base.py", line 3364, in _wrap_pool_connect
    Connection._handle_dbapi_exception_noconnection(
  File "/usr/lib/python3.11/site-packages/sqlalchemy/engine/base.py", line 2198, in _handle_dbapi_exception_noconnection
    util.raise_(
  File "/usr/lib/python3.11/site-packages/sqlalchemy/util/compat.py", line 210, in raise_
    raise exception
  File "/usr/lib/python3.11/site-packages/sqlalchemy/engine/base.py", line 3361, in _wrap_pool_connect
    return fn()
           ^^^^
  File "/usr/lib/python3.11/site-packages/sqlalchemy/pool/base.py", line 325, in connect
    return _ConnectionFairy._checkout(self)
           ^^^^^^^^^^^^^^^^^^^^^^^^^^^^^^^^
  File "/usr/lib/python3.11/site-packages/sqlalchemy/pool/base.py", line 888, in _checkout
    fairy = _ConnectionRecord.checkout(pool)
            ^^^^^^^^^^^^^^^^^^^^^^^^^^^^^^^^
  File "/usr/lib/python3.11/site-packages/sqlalchemy/pool/base.py", line 491, in checkout
    rec = pool._do_get()
          ^^^^^^^^^^^^^^
  File "/usr/lib/python3.11/site-packages/sqlalchemy/pool/impl.py", line 145, in _do_get
    with util.safe_reraise():
  File "/usr/lib/python3.11/site-packages/sqlalchemy/util/langhelpers.py", line 70, in __exit__
    compat.raise_(
  File "/usr/lib/python3.11/site-packages/sqlalchemy/util/compat.py", line 210, in raise_
    raise exception
  File "/usr/lib/python3.11/site-packages/sqlalchemy/pool/impl.py", line 143, in _do_get
    return self._create_connection()
           ^^^^^^^^^^^^^^^^^^^^^^^^^
  File "/usr/lib/python3.11/site-packages/sqlalchemy/pool/base.py", line 271, in _create_connection
    return _ConnectionRecord(self)
           ^^^^^^^^^^^^^^^^^^^^^^^
  File "/usr/lib/python3.11/site-packages/sqlalchemy/pool/base.py", line 386, in __init__
    self.__connect()
  File "/usr/lib/python3.11/site-packages/sqlalchemy/pool/base.py", line 684, in __connect
    with util.safe_reraise():
  File "/usr/lib/python3.11/site-packages/sqlalchemy/util/langhelpers.py", line 70, in __exit__
    compat.raise_(
  File "/usr/lib/python3.11/site-packages/sqlalchemy/util/compat.py", line 210, in raise_
    raise exception
  File "/usr/lib/python3.11/site-packages/sqlalchemy/pool/base.py", line 680, in __connect
    self.dbapi_connection = connection = pool._invoke_creator(self)
                                         ^^^^^^^^^^^^^^^^^^^^^^^^^^
  File "/usr/lib/python3.11/site-packages/sqlalchemy/engine/create.py", line 578, in connect
    return dialect.connect(*cargs, **cparams)
           ^^^^^^^^^^^^^^^^^^^^^^^^^^^^^^^^^^
  File "/usr/lib/python3.11/site-packages/sqlalchemy/engine/default.py", line 598, in connect
    return self.dbapi.connect(*cargs, **cparams)
           ^^^^^^^^^^^^^^^^^^^^^^^^^^^^^^^^^^^^^
  File "/usr/lib/python3.11/site-packages/MySQLdb/__init__.py", line 123, in Connect
    return Connection(*args, **kwargs)
           ^^^^^^^^^^^^^^^^^^^^^^^^^^^
  File "/usr/lib/python3.11/site-packages/MySQLdb/connections.py", line 185, in __init__
    super().__init__(*args, **kwargs2)
sqlalchemy.exc.OperationalError: (MySQLdb.OperationalError) (1045, "Access denied for user 'hbnb_test'@'localhost' (using password: YES)")
(Background on this error at: https://sqlalche.me/e/14/e3q8)


======================================================================
ERROR: test_models.test_engine.test_db_storage (unittest.loader._FailedTest.test_models.test_engine.test_db_storage)
----------------------------------------------------------------------
ImportError: Failed to import test module: test_models.test_engine.test_db_storage
Traceback (most recent call last):
  File "/usr/lib/python3.11/site-packages/sqlalchemy/engine/base.py", line 3361, in _wrap_pool_connect
    return fn()
           ^^^^
  File "/usr/lib/python3.11/site-packages/sqlalchemy/pool/base.py", line 325, in connect
    return _ConnectionFairy._checkout(self)
           ^^^^^^^^^^^^^^^^^^^^^^^^^^^^^^^^
  File "/usr/lib/python3.11/site-packages/sqlalchemy/pool/base.py", line 888, in _checkout
    fairy = _ConnectionRecord.checkout(pool)
            ^^^^^^^^^^^^^^^^^^^^^^^^^^^^^^^^
  File "/usr/lib/python3.11/site-packages/sqlalchemy/pool/base.py", line 491, in checkout
    rec = pool._do_get()
          ^^^^^^^^^^^^^^
  File "/usr/lib/python3.11/site-packages/sqlalchemy/pool/impl.py", line 145, in _do_get
    with util.safe_reraise():
  File "/usr/lib/python3.11/site-packages/sqlalchemy/util/langhelpers.py", line 70, in __exit__
    compat.raise_(
  File "/usr/lib/python3.11/site-packages/sqlalchemy/util/compat.py", line 210, in raise_
    raise exception
  File "/usr/lib/python3.11/site-packages/sqlalchemy/pool/impl.py", line 143, in _do_get
    return self._create_connection()
           ^^^^^^^^^^^^^^^^^^^^^^^^^
  File "/usr/lib/python3.11/site-packages/sqlalchemy/pool/base.py", line 271, in _create_connection
    return _ConnectionRecord(self)
           ^^^^^^^^^^^^^^^^^^^^^^^
  File "/usr/lib/python3.11/site-packages/sqlalchemy/pool/base.py", line 386, in __init__
    self.__connect()
  File "/usr/lib/python3.11/site-packages/sqlalchemy/pool/base.py", line 684, in __connect
    with util.safe_reraise():
  File "/usr/lib/python3.11/site-packages/sqlalchemy/util/langhelpers.py", line 70, in __exit__
    compat.raise_(
  File "/usr/lib/python3.11/site-packages/sqlalchemy/util/compat.py", line 210, in raise_
    raise exception
  File "/usr/lib/python3.11/site-packages/sqlalchemy/pool/base.py", line 680, in __connect
    self.dbapi_connection = connection = pool._invoke_creator(self)
                                         ^^^^^^^^^^^^^^^^^^^^^^^^^^
  File "/usr/lib/python3.11/site-packages/sqlalchemy/engine/create.py", line 578, in connect
    return dialect.connect(*cargs, **cparams)
           ^^^^^^^^^^^^^^^^^^^^^^^^^^^^^^^^^^
  File "/usr/lib/python3.11/site-packages/sqlalchemy/engine/default.py", line 598, in connect
    return self.dbapi.connect(*cargs, **cparams)
           ^^^^^^^^^^^^^^^^^^^^^^^^^^^^^^^^^^^^^
  File "/usr/lib/python3.11/site-packages/MySQLdb/__init__.py", line 123, in Connect
    return Connection(*args, **kwargs)
           ^^^^^^^^^^^^^^^^^^^^^^^^^^^
  File "/usr/lib/python3.11/site-packages/MySQLdb/connections.py", line 185, in __init__
    super().__init__(*args, **kwargs2)
MySQLdb.OperationalError: (1045, "Access denied for user 'hbnb_test'@'localhost' (using password: YES)")

The above exception was the direct cause of the following exception:

Traceback (most recent call last):
  File "/usr/lib/python3.11/unittest/loader.py", line 419, in _find_test_path
    module = self._get_module_from_name(name)
             ^^^^^^^^^^^^^^^^^^^^^^^^^^^^^^^^
  File "/usr/lib/python3.11/unittest/loader.py", line 362, in _get_module_from_name
    __import__(name)
  File "/home/meta-bay/workspace/AirBnB_clone_v3/tests/test_models/test_engine/test_db_storage.py", line 8, in <module>
    import models
  File "/home/meta-bay/workspace/AirBnB_clone_v3/models/__init__.py", line 13, in <module>
    storage = DBStorage()
              ^^^^^^^^^^^
  File "/hoctions.py", line 185, in __init__
    super().__init__(*args, **kwargs2)
sqlalchemy.exc.OperationalError: (MySQLdb.OperationalError) (1045, "Access denied for user 'hbnb_test'@'localhost' (using password: YES)")
(Background on this error at: https://sqlalche.me/e/14/e3q8)


======================================================================
ERROR: test_models.test_engine.test_db_storage (unittest.loader._FailedTest.test_models.test_engine.test_db_storage)
----------------------------------------------------------------------
ImportError: Failed to import test module: test_models.test_engine.test_db_storage
Traceback (most recent call last):
  File "/usr/lib/python3.11/site-packages/sqlalchemy/engine/base.py", line 3361, in _wrap_pool_connect
    return fn()
           ^^^^
  File "/usr/lib/python3.11/site-packages/sqlalchemy/pool/base.py", line 325, in connect
    return _ConnectionFairy._checkout(self)
           ^^^^^^^^^^^^^^^^^^^^^^^^^^^^^^^^
  File "/usr/lib/python3.11/site-packages/sqlalchemy/pool/base.py", line 888, in _checkout
    fairy = _ConnectionRecord.checkout(pool)
            ^^^^^^^^^^^^^^^^^^^^^^^^^^^^^^^^
  File "/usr/lib/python3.11/site-packages/sqlalchemy/pool/base.py", line 491, in checkout
    rec = pool._do_get()
          ^^^^^^^^^^^^^^
  File "/usr/lib/python3.11/site-packages/sqlalchemy/pool/impl.py", line 145, in _do_get
    with util.safe_reraise():
  File "/usr/lib/python3.11/site-packages/sqlalchemy/util/langhelpers.py", line 70, in __exit__
    compat.raise_(
  File "/usr/lib/python3.11/site-packages/sqlalchemy/util/compat.py", line 210, in raise_
    raise exception
  File "/usr/lib/python3.11/site-packages/sqlalchemy/pool/impl.py", line 143, in _do_get
    return self._create_connection()
           ^^^^^^^^^^^^^^^^^^^^^^^^^
  File "/usr/lib/python3.11/site-packages/sqlalchemy/pool/base.py", line 271, in _create_connection
    return _ConnectionRecord(self)
           ^^^^^^^^^^^^^^^^^^^^^^^
  File "/usr/lib/python3.11/site-packages/sqlalchemy/pool/base.py", line 386, in __init__
    self.__connect()
  File "/usr/lib/python3.11/site-packages/sqlalchemy/pool/base.py", line 684, in __connect
    with util.safe_reraise():
  File "/usr/lib/python3.11/site-packages/sqlalchemy/util/langhelpers.py", line 70, in __exit__
    compat.raise_(
  File "/usr/lib/python3.11/site-packages/sqlalchemy/util/compat.py", line 210, in raise_
    raise exception
  File "/usr/lib/python3.11/site-packages/sqlalchemy/pool/base.py", line 680, in __connect
    self.dbapi_connection = connection = pool._invoke_creator(self)
                                         ^^^^^^^^^^^^^^^^^^^^^^^^^^
  File "/usr/lib/python3.11/site-packages/sqlalchemy/engine/create.py", line 578, in connect
    return dialect.connect(*cargs, **cparams)
           ^^^^^^^^^^^^^^^^^^^^^^^^^^^^^^^^^^
  File "/usr/lib/python3.11/site-packages/sqlalchemy/engine/default.py", line 598, in connect
    return self.dbapi.connect(*cargs, **cparams)
           ^^^^^^^^^^^^^^^^^^^^^^^^^^^^^^^^^^^^^
  File "/usr/lib/python3.11/site-packages/MySQLdb/__init__.py", line 123, in Connect
    return Connection(*args, **kwargs)
           ^^^^^^^^^^^^^^^^^^^^^^^^^^^
  File "/usr/lib/python3.11/site-packages/MySQLdb/connections.py", line 185, in __init__
    super().__init__(*args, **kwargs2)
MySQLdb.OperationalError: (1045, "Access denied for user 'hbnb_test'@'localhost' (using password: YES)")

The above exception was the direct cause of the following exception:

Traceback (most recent call last):
  File "/usr/lib/python3.11/unittest/loader.py", line 419, in _find_test_path
    module = self._get_module_from_name(name)
             ^^^^^^^^^^^^^^^^^^^^^^^^^^^^^^^^
  File "/usr/lib/python3.11/unittest/loader.py", line 362, in _get_module_from_name
    __import__(name)
  File "/home/meta-bay/workspace/AirBnB_clone_v3/tests/test_models/test_engine/test_db_storage.py", line 8, in <module>
    import models
  File "/home/meta-bay/workspace/AirBnB_clone_v3/models/__init__.py", line 13, in <module>
    storage = DBStorage()
              ^^^^^^^^^^^
  File "/home/meta-bay/workspace/AirBnB_clone_v3/models/engine/db_storage.py", line 41, in __init__
    Base.metadata.drop_all(self.__engine)
  File "/usr/lib/python3.11/site-packages/sqlalchemy/sql/schema.py", line 4959, in drop_all
    bind._run_ddl_visitor(
  File "/usr/lib/python3.11/site-packages/sqlalchemy/engine/base.py", line 3227, in _run_ddl_visitor
    with self.begin() as conn:
         ^^^^^^^^^^^^
  File "/usr/lib/python3.11/site-packages/sqlalchemy/engine/base.py", line 3143, in begin
    conn = self.connect(close_with_result=close_with_result)
           ^^^^^^^^^^^^^^^^^^^^^^^^^^^^^^^^^^^^^^^^^^^^^^^^^
  File "/usr/lib/python3.11/site-packages/sqlalchemy/engine/base.py", line 3315, in connect
    return self._connection_cls(self, close_with_result=close_with_result)
           ^^^^^^^^^^^^^^^^^^^^^^^^^^^^^^^^^^^^^^^^^^^^^^^^^^^^^^^^^^^^^^^
  File "/usr/lib/python3.11/site-packages/sqlalchemy/engine/base.py", line 96, in __init__
    else engine.raw_connection()
         ^^^^^^^^^^^^^^^^^^^^^^^
  File "/usr/lib/python3.11/site-packages/sqlalchemy/engine/base.py", line 3394, in raw_connection
    return self._wrap_pool_connect(self.pool.connect, _connection)
           ^^^^^^^^^^^^^^^^^^^^^^^^^^^^^^^^^^^^^^^^^^^^^^^^^^^^^^^
  File "/usr/lib/python3.11/site-packages/sqlalchemy/engine/base.py", line 3364, in _wrap_pool_connect
    Connection._handle_dbapi_exception_noconnection(
  File "/usr/lib/python3.11/site-packages/sqlalchemy/engine/base.py", line 2198, in _handle_dbapi_exception_noconnection
    util.raise_(
  File "/usr/lib/python3.11/site-packages/sqlalchemy/util/compat.py", line 210, in raise_
    raise exception
  File "/usr/lib/python3.11/site-packages/sqlalchemy/engine/base.py", line 3361, in _wrap_pool_connect
    return fn()
           ^^^^
  File "/usr/lib/python3.11/site-packages/sqlalchemy/pool/base.py", line 325, in connect
    return _ConnectionFairy._checkout(self)
           ^^^^^^^^^^^^^^^^^^^^^^^^^^^^^^^^
  File "/usr/lib/python3.11/site-packages/sqlalchemy/pool/base.py", line 888, in _checkout
    fairy = _ConnectionRecord.checkout(pool)
            ^^^^^^^^^^^^^^^^^^^^^^^^^^^^^^^^
  File "/usr/lib/python3.11/site-packages/sqlalchemy/pool/base.py", line 491, in checkout
    rec = pool._do_get()
          ^^^^^^^^^^^^^^
  File "/usr/lib/python3.11/site-packages/sqlalchemy/pool/impl.py", line 145, in _do_get
    with util.safe_reraise():
  File "/usr/lib/python3.11/site-packages/sqlalchemy/util/langhelpers.py", line 70, in __exit__
    compat.raise_(
  File "/usr/lib/python3.11/site-packages/sqlalchemy/util/compat.py", line 210, in raise_
    raise exception
  File "/usr/lib/python3.11/site-packages/sqlalchemy/pool/impl.py", line 143, in _do_get
    return self._create_connection()
           ^^^^^^^^^^^^^^^^^^^^^^^^^
  File "/usr/lib/python3.11/site-packages/sqlalchemy/pool/base.py", line 271, in _create_connection
    return _ConnectionRecord(self)
           ^^^^^^^^^^^^^^^^^^^^^^^
  File "/usr/lib/python3.11/site-packages/sqlalchemy/pool/base.py", line 386, in __init__
    self.__connect()
  File "/usr/lib/python3.11/site-packages/sqlalchemy/pool/base.py", line 684, in __connect
    with util.safe_reraise():
  File "/usr/lib/python3.11/site-packages/sqlalchemy/util/langhelpers.py", line 70, in __exit__
    compat.raise_(
  File "/usr/lib/python3.11/site-packages/sqlalchemy/util/compat.py", line 210, in raise_
    raise exception
  File "/usr/lib/python3.11/site-packages/sqlalchemy/pool/base.py", line 680, in __connect
    self.dbapi_connection = connection = pool._invoke_creator(self)
                                         ^^^^^^^^^^^^^^^^^^^^^^^^^^
  File "/usr/lib/python3.11/site-packages/sqlalchemy/engine/create.py", line 578, in connect
    return dialect.connect(*cargs, **cparams)
           ^^^^^^^^^^^^^^^^^^^^^^^^^^^^^^^^^^
  File "/usr/lib/python3.11/site-packages/sqlalchemy/engine/default.py", line 598, in connect
    return self.dbapi.connect(*cargs, **cparams)
           ^^^^^^^^^^^^^^^^^^^^^^^^^^^^^^^^^^^^^
  File "/usr/lib/python3.11/site-packages/MySQLdb/__init__.py", line me/meta-bay/workspace/AirBnB_clone_v3/models/engine/db_storage.py", line 41, in __init__
    Base.metadata.drop_all(self.__engine)
  File "/usr/lib/python3.11/site-packages/sqlalchemy/sql/schema.py", line 4959, in drop_all
    bind._run_ddl_visitor(
  File "/usr/lib/python3.11/site-packages/sqlalchemy/engine/base.py", line 3227, in _run_ddl_visitor
    with self.begin() as conn:
         ^^^^^^^^^^^^
  File "/usr/lib/python3.11/site-packages/sqlalchemy/engine/base.py", line 3143, in begin
    conn = self.connect(close_with_result=close_with_result)
           ^^^^^^^^^^^^^^^^^^^^^^^^^^^^^^^^^^^^^^^^^^^^^^^^^
  File "/usr/lib/python3.11/site-packages/sqlalchemy/engine/base.py", line 3315, in connect
    return self._connection_cls(self, close_with_result=close_with_result)
           ^^^^^^^^^^^^^^^^^^^^^^^^^^^^^^^^^^^^^^^^^^^^^^^^^^^^^^^^^^^^^^^
  File "/usr/lib/python3.11/site-packages/sqlalchemy/engine/base.py", line 96, in __init__
    else engine.raw_connection()
         ^^^^^^^^^^^^^^^^^^^^^^^
  File "/usr/lib/python3.11/site-packages/sqlalchemy/engine/base.py", line 3394, in raw_connection
    return self._wrap_pool_connect(self.pool.connect, _connection)
           ^^^^^^^^^^^^^^^^^^^^^^^^^^^^^^^^^^^^^^^^^^^^^^^^^^^^^^^
  File "/usr/lib/python3.11/site-packages/sqlalchemy/engine/base.py", line 3364, in _wrap_pool_connect
    Connection._handle_dbapi_exception_noconnection(
  File "/usr/lib/python3.11/site-packages/sqlalchemy/engine/base.py", line 2198, in _handle_dbapi_exception_noconnection
    util.raise_(
  File "/usr/lib/python3.11/site-packages/sqlalchemy/util/compat.py", line 210, in raise_
    raise exception
  File "/usr/lib/python3.11/site-packages/sqlalchemy/engine/base.py", line 3361, in _wrap_pool_connect
    return fn()
           ^^^^
  File "/usr/lib/python3.11/site-packages/sqlalchemy/pool/base.py", line 325, in connect
    return _ConnectionFairy._checkout(self)
           ^^^^^^^^^^^^^^^^^^^^^^^^^^^^^^^^
  File "/usr/lib/python3.11/site-packages/sqlalchemy/pool/base.py", line 888, in _checkout
    fairy = _ConnectionRecord.checkout(pool)
            ^^^^^^^^^^^^^^^^^^^^^^^^^^^^^^^^
  File "/usr/lib/python3.11/site-packages/sqlalchemy/pool/base.py", line 491, in checkout
    rec = pool._do_get()
          ^^^^^^^^^^^^^^
  File "/usr/lib/python3.11/site-packages/sqlalchemy/pool/impl.py", line 145, in _do_get
    with util.safe_reraise():
  File "/usr/lib/python3.11/site-packages/sqlalchemy/util/langhelpers.py", line 70, in __exit__
    compat.raise_(
  File "/usr/lib/python3.11/site-packages/sqlalchemy/util/compat.py", line 210, in raise_
    raise exception
  File "/usr/lib/python3.11/site-packages/sqlalchemy/pool/impl.py", line 143, in _do_get
    return self._create_connection()
           ^^^^^^^^^^^^^^^^^^^^^^^^^
  File "/usr/lib/python3.11/site-packages/sqlalchemy/pool/base.py", line 271, in _create_connection
    return _ConnectionRecord(self)
           ^^^^^^^^^^^^^^^^^^^^^^^
  File "/usr/lib/python3.11/site-packages/sqlalchemy/pool/base.py", line 386, in __init__
    self.__connect()
  File "/usr/lib/python3.11/site-packages/sqlalchemy/pool/base.py", line 684, in __connect
    with util.safe_reraise():
  File "/usr/lib/python3.11/site-packages/sqlalchemy/util/langhelpers.py", line 70, in __exit__
    compat.raise_(
  File "/usr/lib/python3.11/site-packages/sqlalchemy/util/compat.py", line 210, in raise_
    raise exception
  File "/usr/lib/python3.11/site-packages/sqlalchemy/pool/base.py", line 680, in __connect
    self.dbapi_connection = connection = pool._invoke_creator(self)
                                         ^^^^^^^^^^^^^^^^^^^^^^^^^^
  File "/usr/lib/python3.11/site-packages/sqlalchemy/engine/create.py", line 578, in connect
    return dialect.connect(*cargs, **cparams)
           ^^^^^^^^^^^^^^^^^^^^^^^^^^^^^^^^^^
  File "/usr/lib/python3.11/site-packages/sqlalchemy/engine/default.py", line 598, in connect
    return self.dbapi.connect(*cargs, **cparams)
           ^^^^^^^^^^^^^^^^^^^^^^^^^^^^^^^^^^^^^
  File "/usr/lib/python3.11/site-packages/MySQLdb/__init__.py", line 123, in Connect
    return Connection(*args, **kwargs)
           ^^^^^^^^^^^^^^^^^^^^^^^^^^^
  File "/usr/lib/python3.11/site-packages/MySQLdb/connections.py", line 185, in __init__
    super().__init__(*args, **kwargs2)
sqlalchemy.exc.OperationalError: (MySQLdb.OperationalError) (1045, "Access denied for user 'hbnb_test'@'localhost' (using password: YES)")
(Background on this error at: https://sqlalche.me/e/14/e3q8)


======================================================================
ERROR: test_models.test_engine.test_file_storage (unittest.loader._FailedTest.test_models.test_engine.test_file_storage)
----------------------------------------------------------------------
ImportError: Failed to import test module: test_models.test_engine.test_file_storage
Traceback (most recent call last):
  File "/usr/lib/python3.11/site-packages/sqlalchemy/engine/base.py", line 3361, in _wrap_pool_connect
    return fn()
           ^^^^
  File "/usr/lib/python3.11/site-packages/sqlalchemy/pool/base.py", line 325, in connect
    return _ConnectionFairy._checkout(self)
           ^^^^^^^^^^^^^^^^^^^^^^^^^^^^^^^^
  File "/usr/lib/python3.11/site-packages/sqlalchemy/pool/base.py", line 888, in _checkout
    fairy = _ConnectionRecord.checkout(pool)
            ^^^^^^^^^^^^^^^^^^^^^^^^^^^^^^^^
  File "/usr/lib/python3.11/site-packages/sqlalchemy/pool/base.py", line 491, in checkout
    rec = pool._do_get()
          ^^^^^^^^^^^^^^
  File "/usr/lib/python3.11/site-packages/sqlalchemy/pool/impl.py", line 145, in _do_get
    with util.safe_reraise():
  File "/usr/lib/python3.11/site-packages/sqlalchemy/util/langhelpers.py", line 70, in __exit__
    compat.raise_(
  File "/usr/lib/python3.11/site-packages/sqlalchemy/util/compat.py", line 210, in raise_
    raise exception
  File "/usr/lib/python3.11/site-packages/sqlalchemy/pool/impl.py", line 143, in _do_get
    return self._create_connection()
           ^^^^^^^^^^^^^^^^^^^^^^^^^
  File "/usr/lib/python3.11/site-packages/sqlalchemy/pool/base.py", line 271, in _create_connection
    return _ConnectionRecord(self)
           ^^^^^^^^^^^^^^^^^^^^^^^
  File "/usr/lib/python3.11/site-packages/sqlalchemy/pool/base.py", line 386, in __init__
    self.__connect()
  File "/usr/lib/python3.11/site-packages/sqlalchemy/pool/base.py", line 684, in __connect
    with util.safe_reraise():
  File "/usr/lib/python3.11/site-packages/sqlalchemy/util/langhelpers.py", line 70, in __exit__
    compat.raise_(
  File "/usr/lib/python3.11/site-packages/sqlalchemy/util/compat.py", line 210, in raise_
    raise exception
  File "/usr/lib/python3.11/site-packages/sqlalchemy/pool/base.py", line 680, in __connect
    self.dbapi_connection = connection = pool._invoke_creator(self)
                                         ^^^^^^^^^^^^^^^^^^^^^^^^^^
  File "/usr/lib/python3.11/site-packages/sqlalchemy/engine/create.py", line 578, in connect
    return dialect.connect(*cargs, **cparams)
           ^^^^^^^^^^^^^^^^^^^^^^^^^^^^^^^^^^
  File "/usr/lib/python3.11/site-packages/sqlalchemy/engine/default.py", line 598, in connect
    return self.dbapi.connect(*cargs, **cparams)
           ^^^^^^^^^^^^^^^^^^^^^^^^^^^^^^^^^^^^^
  File "/usr/lib/python3.11/site-packages/MySQLdb/__init__.py", line 123, in Connect
    return Connection(*args, **kwargs)
           ^^^^^^^^^^^^^^^^^^^^^^^^^^^
  File "/usr/lib/python3.11/site-packages/MySQLdb/connections.py", line 185, in __init__
    super().__init__(*args, **kwargs2)
MySQLdb.OperationalError: (1045, "Access denied for user 'hbnb_test'@'localhost' (using password: YES)")

The above exception was the direct cause of the following exception:

Traceback (most recent call last):
  File "/usr/lib/python3.11/unittest/loader.py", line 419, in _find_test_path
    module = self._get_module_from_name(name)
             ^^^^^^^^^^^^^^^^^^^^^^^^^^^^^^^^
  File "/usr/lib/python3.11/unittest/loader.py", line 362, in _get_module_from_name
    __import__(name)
  File "/home/meta-bay/workspace/AirBnB_clone_v3/tests/test_models/test_engine/test_file_storage.py", line 8, in <module>
    import mode123, in Connect
    return Connection(*args, **kwargs)
           ^^^^^^^^^^^^^^^^^^^^^^^^^^^
  File "/usr/lib/python3.11/site-packages/MySQLdb/connections.py", line 185, in __init__
    super().__init__(*args, **kwargs2)
sqlalchemy.exc.OperationalError: (MySQLdb.OperationalError) (1045, "Access denied for user 'hbnb_test'@'localhost' (using password: YES)")
(Background on this error at: https://sqlalche.me/e/14/e3q8)


======================================================================
ERROR: test_models.test_engine.test_file_storage (unittest.loader._FailedTest.test_models.test_engine.test_file_storage)
----------------------------------------------------------------------
ImportError: Failed to import test module: test_models.test_engine.test_file_storage
Traceback (most recent call last):
  File "/usr/lib/python3.11/site-packages/sqlalchemy/engine/base.py", line 3361, in _wrap_pool_connect
    return fn()
           ^^^^
  File "/usr/lib/python3.11/site-packages/sqlalchemy/pool/base.py", line 325, in connect
    return _ConnectionFairy._checkout(self)
           ^^^^^^^^^^^^^^^^^^^^^^^^^^^^^^^^
  File "/usr/lib/python3.11/site-packages/sqlalchemy/pool/base.py", line 888, in _checkout
    fairy = _ConnectionRecord.checkout(pool)
            ^^^^^^^^^^^^^^^^^^^^^^^^^^^^^^^^
  File "/usr/lib/python3.11/site-packages/sqlalchemy/pool/base.py", line 491, in checkout
    rec = pool._do_get()
          ^^^^^^^^^^^^^^
  File "/usr/lib/python3.11/site-packages/sqlalchemy/pool/impl.py", line 145, in _do_get
    with util.safe_reraise():
  File "/usr/lib/python3.11/site-packages/sqlalchemy/util/langhelpers.py", line 70, in __exit__
    compat.raise_(
  File "/usr/lib/python3.11/site-packages/sqlalchemy/util/compat.py", line 210, in raise_
    raise exception
  File "/usr/lib/python3.11/site-packages/sqlalchemy/pool/impl.py", line 143, in _do_get
    return self._create_connection()
           ^^^^^^^^^^^^^^^^^^^^^^^^^
  File "/usr/lib/python3.11/site-packages/sqlalchemy/pool/base.py", line 271, in _create_connection
    return _ConnectionRecord(self)
           ^^^^^^^^^^^^^^^^^^^^^^^
  File "/usr/lib/python3.11/site-packages/sqlalchemy/pool/base.py", line 386, in __init__
    self.__connect()
  File "/usr/lib/python3.11/site-packages/sqlalchemy/pool/base.py", line 684, in __connect
    with util.safe_reraise():
  File "/usr/lib/python3.11/site-packages/sqlalchemy/util/langhelpers.py", line 70, in __exit__
    compat.raise_(
  File "/usr/lib/python3.11/site-packages/sqlalchemy/util/compat.py", line 210, in raise_
    raise exception
  File "/usr/lib/python3.11/site-packages/sqlalchemy/pool/base.py", line 680, in __connect
    self.dbapi_connection = connection = pool._invoke_creator(self)
                                         ^^^^^^^^^^^^^^^^^^^^^^^^^^
  File "/usr/lib/python3.11/site-packages/sqlalchemy/engine/create.py", line 578, in connect
    return dialect.connect(*cargs, **cparams)
           ^^^^^^^^^^^^^^^^^^^^^^^^^^^^^^^^^^
  File "/usr/lib/python3.11/site-packages/sqlalchemy/engine/default.py", line 598, in connect
    return self.dbapi.connect(*cargs, **cparams)
           ^^^^^^^^^^^^^^^^^^^^^^^^^^^^^^^^^^^^^
  File "/usr/lib/python3.11/site-packages/MySQLdb/__init__.py", line 123, in Connect
    return Connection(*args, **kwargs)
           ^^^^^^^^^^^^^^^^^^^^^^^^^^^
  File "/usr/lib/python3.11/site-packages/MySQLdb/connections.py", line 185, in __init__
    super().__init__(*args, **kwargs2)
MySQLdb.OperationalError: (1045, "Access denied for user 'hbnb_test'@'localhost' (using password: YES)")

The above exception was the direct cause of the following exception:

Traceback (most recent call last):
  File "/usr/lib/python3.11/unittest/loader.py", line 419, in _find_test_path
    module = self._get_module_from_name(name)
             ^^^^^^^^^^^^^^^^^^^^^^^^^^^^^^^^
  File "/usr/lib/python3.11/unittest/loader.py", line 362, in _get_module_from_name
    __import__(name)
  File "/home/meta-bay/workspace/AirBnB_clone_v3/tests/test_models/test_engine/test_file_storage.py", line 8, in <module>
    import models
  File "/home/meta-bay/workspace/AirBnB_clone_v3/models/__init__.py", line 13, in <module>
    storage = DBStorage()
              ^^^^^^^^^^^
  File "/home/meta-bay/workspace/AirBnB_clone_v3/models/engine/db_storage.py", line 41, in __init__
    Base.metadata.drop_all(self.__engine)
  File "/usr/lib/python3.11/site-packages/sqlalchemy/sql/schema.py", line 4959, in drop_all
    bind._run_ddl_visitor(
  File "/usr/lib/python3.11/site-packages/sqlalchemy/engine/base.py", line 3227, in _run_ddl_visitor
    with self.begin() as conn:
         ^^^^^^^^^^^^
  File "/usr/lib/python3.11/site-packages/sqlalchemy/engine/base.py", line 3143, in begin
    conn = self.connect(close_with_result=close_with_result)
           ^^^^^^^^^^^^^^^^^^^^^^^^^^^^^^^^^^^^^^^^^^^^^^^^^
  File "/usr/lib/python3.11/site-packages/sqlalchemy/engine/base.py", line 3315, in connect
    return self._connection_cls(self, close_with_result=close_with_result)
           ^^^^^^^^^^^^^^^^^^^^^^^^^^^^^^^^^^^^^^^^^^^^^^^^^^^^^^^^^^^^^^^
  File "/usr/lib/python3.11/site-packages/sqlalchemy/engine/base.py", line 96, in __init__
    else engine.raw_connection()
         ^^^^^^^^^^^^^^^^^^^^^^^
  File "/usr/lib/python3.11/site-packages/sqlalchemy/engine/base.py", line 3394, in raw_connection
    return self._wrap_pool_connect(self.pool.connect, _connection)
           ^^^^^^^^^^^^^^^^^^^^^^^^^^^^^^^^^^^^^^^^^^^^^^^^^^^^^^^
  File "/usr/lib/python3.11/site-packages/sqlalchemy/engine/base.py", line 3364, in _wrap_pool_connect
    Connection._handle_dbapi_exception_noconnection(
  File "/usr/lib/python3.11/site-packages/sqlalchemy/engine/base.py", line 2198, in _handle_dbapi_exception_noconnection
    util.raise_(
  File "/usr/lib/python3.11/site-packages/sqlalchemy/util/compat.py", line 210, in raise_
    raise exception
  File "/usr/lib/python3.11/site-packages/sqlalchemy/engine/base.py", line 3361, in _wrap_pool_connect
    return fn()
           ^^^^
  File "/usr/lib/python3.11/site-packages/sqlalchemy/pool/base.py", line 325, in connect
    return _ConnectionFairy._checkout(self)
           ^^^^^^^^^^^^^^^^^^^^^^^^^^^^^^^^
  File "/usr/lib/python3.11/site-packages/sqlalchemy/pool/base.py", line 888, in _checkout
    fairy = _ConnectionRecord.checkout(pool)
            ^^^^^^^^^^^^^^^^^^^^^^^^^^^^^^^^
  File "/usr/lib/python3.11/site-packages/sqlalchemy/pool/base.py", line 491, in checkout
    rec = pool._do_get()
          ^^^^^^^^^^^^^^
  File "/usr/lib/python3.11/site-packages/sqlalchemy/pool/impl.py", line 145, in _do_get
    with util.safe_reraise():
  File "/usr/lib/python3.11/site-packages/sqlalchemy/util/langhelpers.py", line 70, in __exit__
    compat.raise_(
  File "/usr/lib/python3.11/site-packages/sqlalchemy/util/compat.py", line 210, in raise_
    raise exception
  File "/usr/lib/python3.11/site-packages/sqlalchemy/pool/impl.py", line 143, in _do_get
    return self._create_connection()
           ^^^^^^^^^^^^^^^^^^^^^^^^^
  File "/usr/lib/python3.11/site-packages/sqlalchemy/pool/base.py", line 271, in _create_connection
    return _ConnectionRecord(self)
           ^^^^^^^^^^^^^^^^^^^^^^^
  File "/usr/lib/python3.11/site-packages/sqlalchemy/pool/base.py", line 386, in __init__
    self.__connect()
  File "/usr/lib/python3.11/site-packages/sqlalchemy/pool/base.py", line 684, in __connect
    with util.safe_reraise():
  File "/usr/lib/python3.11/site-packages/sqlalchemy/util/langhelpers.py", line 70, in __exit__
    compat.raise_(
  File "/usr/lib/python3.11/site-packages/sqlalchemy/util/compat.py", line 210, in raise_
    raise exception
  File "/usr/lib/python3.11/site-packages/sqlalchemy/pool/base.py", line 680, in __connect
    self.dbapi_connection = connection = pool._invoke_creator(self)
                                         ^^^^^^^^^^^^^^^^^^^^^^^^^^
  File "/usr/lib/python3.11/site-packages/sqlalchemy/engine/create.py", line 578, in connect
    return dialect.connect(*cargs, **cparams)
           ^^^^^^^^^^^^^^^^^^^^^^^^^^^^^^^^^^
  File "/usr/lib/python3.11/site-packages/sqlalchemy/engine/default.py", line 598, in connect
    returnls
  File "/home/meta-bay/workspace/AirBnB_clone_v3/models/__init__.py", line 13, in <module>
    storage = DBStorage()
              ^^^^^^^^^^^
  File "/home/meta-bay/workspace/AirBnB_clone_v3/models/engine/db_storage.py", line 41, in __init__
    Base.metadata.drop_all(self.__engine)
  File "/usr/lib/python3.11/site-packages/sqlalchemy/sql/schema.py", line 4959, in drop_all
    bind._run_ddl_visitor(
  File "/usr/lib/python3.11/site-packages/sqlalchemy/engine/base.py", line 3227, in _run_ddl_visitor
    with self.begin() as conn:
         ^^^^^^^^^^^^
  File "/usr/lib/python3.11/site-packages/sqlalchemy/engine/base.py", line 3143, in begin
    conn = self.connect(close_with_result=close_with_result)
           ^^^^^^^^^^^^^^^^^^^^^^^^^^^^^^^^^^^^^^^^^^^^^^^^^
  File "/usr/lib/python3.11/site-packages/sqlalchemy/engine/base.py", line 3315, in connect
    return self._connection_cls(self, close_with_result=close_with_result)
           ^^^^^^^^^^^^^^^^^^^^^^^^^^^^^^^^^^^^^^^^^^^^^^^^^^^^^^^^^^^^^^^
  File "/usr/lib/python3.11/site-packages/sqlalchemy/engine/base.py", line 96, in __init__
    else engine.raw_connection()
         ^^^^^^^^^^^^^^^^^^^^^^^
  File "/usr/lib/python3.11/site-packages/sqlalchemy/engine/base.py", line 3394, in raw_connection
    return self._wrap_pool_connect(self.pool.connect, _connection)
           ^^^^^^^^^^^^^^^^^^^^^^^^^^^^^^^^^^^^^^^^^^^^^^^^^^^^^^^
  File "/usr/lib/python3.11/site-packages/sqlalchemy/engine/base.py", line 3364, in _wrap_pool_connect
    Connection._handle_dbapi_exception_noconnection(
  File "/usr/lib/python3.11/site-packages/sqlalchemy/engine/base.py", line 2198, in _handle_dbapi_exception_noconnection
    util.raise_(
  File "/usr/lib/python3.11/site-packages/sqlalchemy/util/compat.py", line 210, in raise_
    raise exception
  File "/usr/lib/python3.11/site-packages/sqlalchemy/engine/base.py", line 3361, in _wrap_pool_connect
    return fn()
           ^^^^
  File "/usr/lib/python3.11/site-packages/sqlalchemy/pool/base.py", line 325, in connect
    return _ConnectionFairy._checkout(self)
           ^^^^^^^^^^^^^^^^^^^^^^^^^^^^^^^^
  File "/usr/lib/python3.11/site-packages/sqlalchemy/pool/base.py", line 888, in _checkout
    fairy = _ConnectionRecord.checkout(pool)
            ^^^^^^^^^^^^^^^^^^^^^^^^^^^^^^^^
  File "/usr/lib/python3.11/site-packages/sqlalchemy/pool/base.py", line 491, in checkout
    rec = pool._do_get()
          ^^^^^^^^^^^^^^
  File "/usr/lib/python3.11/site-packages/sqlalchemy/pool/impl.py", line 145, in _do_get
    with util.safe_reraise():
  File "/usr/lib/python3.11/site-packages/sqlalchemy/util/langhelpers.py", line 70, in __exit__
    compat.raise_(
  File "/usr/lib/python3.11/site-packages/sqlalchemy/util/compat.py", line 210, in raise_
    raise exception
  File "/usr/lib/python3.11/site-packages/sqlalchemy/pool/impl.py", line 143, in _do_get
    return self._create_connection()
           ^^^^^^^^^^^^^^^^^^^^^^^^^
  File "/usr/lib/python3.11/site-packages/sqlalchemy/pool/base.py", line 271, in _create_connection
    return _ConnectionRecord(self)
           ^^^^^^^^^^^^^^^^^^^^^^^
  File "/usr/lib/python3.11/site-packages/sqlalchemy/pool/base.py", line 386, in __init__
    self.__connect()
  File "/usr/lib/python3.11/site-packages/sqlalchemy/pool/base.py", line 684, in __connect
    with util.safe_reraise():
  File "/usr/lib/python3.11/site-packages/sqlalchemy/util/langhelpers.py", line 70, in __exit__
    compat.raise_(
  File "/usr/lib/python3.11/site-packages/sqlalchemy/util/compat.py", line 210, in raise_
    raise exception
  File "/usr/lib/python3.11/site-packages/sqlalchemy/pool/base.py", line 680, in __connect
    self.dbapi_connection = connection = pool._invoke_creator(self)
                                         ^^^^^^^^^^^^^^^^^^^^^^^^^^
  File "/usr/lib/python3.11/site-packages/sqlalchemy/engine/create.py", line 578, in connect
    return dialect.connect(*cargs, **cparams)
           ^^^^^^^^^^^^^^^^^^^^^^^^^^^^^^^^^^
  File "/usr/lib/python3.11/site-packages/sqlalchemy/engine/default.py", line 598, in connect
    return self.dbapi.connect(*cargs, **cparams)
           ^^^^^^^^^^^^^^^^^^^^^^^^^^^^^^^^^^^^^
  File "/usr/lib/python3.11/site-packages/MySQLdb/__init__.py", line 123, in Connect
    return Connection(*args, **kwargs)
           ^^^^^^^^^^^^^^^^^^^^^^^^^^^
  File "/usr/lib/python3.11/site-packages/MySQLdb/connections.py", line 185, in __init__
    super().__init__(*args, **kwargs2)
sqlalchemy.exc.OperationalError: (MySQLdb.OperationalError) (1045, "Access denied for user 'hbnb_test'@'localhost' (using password: YES)")
(Background on this error at: https://sqlalche.me/e/14/e3q8)


======================================================================
ERROR: test_models.test_place (unittest.loader._FailedTest.test_models.test_place)
----------------------------------------------------------------------
ImportError: Failed to import test module: test_models.test_place
Traceback (most recent call last):
  File "/usr/lib/python3.11/site-packages/sqlalchemy/engine/base.py", line 3361, in _wrap_pool_connect
    return fn()
           ^^^^
  File "/usr/lib/python3.11/site-packages/sqlalchemy/pool/base.py", line 325, in connect
    return _ConnectionFairy._checkout(self)
           ^^^^^^^^^^^^^^^^^^^^^^^^^^^^^^^^
  File "/usr/lib/python3.11/site-packages/sqlalchemy/pool/base.py", line 888, in _checkout
    fairy = _ConnectionRecord.checkout(pool)
            ^^^^^^^^^^^^^^^^^^^^^^^^^^^^^^^^
  File "/usr/lib/python3.11/site-packages/sqlalchemy/pool/base.py", line 491, in checkout
    rec = pool._do_get()
          ^^^^^^^^^^^^^^
  File "/usr/lib/python3.11/site-packages/sqlalchemy/pool/impl.py", line 145, in _do_get
    with util.safe_reraise():
  File "/usr/lib/python3.11/site-packages/sqlalchemy/util/langhelpers.py", line 70, in __exit__
    compat.raise_(
  File "/usr/lib/python3.11/site-packages/sqlalchemy/util/compat.py", line 210, in raise_
    raise exception
  File "/usr/lib/python3.11/site-packages/sqlalchemy/pool/impl.py", line 143, in _do_get
    return self._create_connection()
           ^^^^^^^^^^^^^^^^^^^^^^^^^
  File "/usr/lib/python3.11/site-packages/sqlalchemy/pool/base.py", line 271, in _create_connection
    return _ConnectionRecord(self)
           ^^^^^^^^^^^^^^^^^^^^^^^
  File "/usr/lib/python3.11/site-packages/sqlalchemy/pool/base.py", line 386, in __init__
    self.__connect()
  File "/usr/lib/python3.11/site-packages/sqlalchemy/pool/base.py", line 684, in __connect
    with util.safe_reraise():
  File "/usr/lib/python3.11/site-packages/sqlalchemy/util/langhelpers.py", line 70, in __exit__
    compat.raise_(
  File "/usr/lib/python3.11/site-packages/sqlalchemy/util/compat.py", line 210, in raise_
    raise exception
  File "/usr/lib/python3.11/site-packages/sqlalchemy/pool/base.py", line 680, in __connect
    self.dbapi_connection = connection = pool._invoke_creator(self)
                                         ^^^^^^^^^^^^^^^^^^^^^^^^^^
  File "/usr/lib/python3.11/site-packages/sqlalchemy/engine/create.py", line 578, in connect
    return dialect.connect(*cargs, **cparams)
           ^^^^^^^^^^^^^^^^^^^^^^^^^^^^^^^^^^
  File "/usr/lib/python3.11/site-packages/sqlalchemy/engine/default.py", line 598, in connect
    return self.dbapi.connect(*cargs, **cparams)
           ^^^^^^^^^^^^^^^^^^^^^^^^^^^^^^^^^^^^^
  File "/usr/lib/python3.11/site-packages/MySQLdb/__init__.py", line 123, in Connect
    return Connection(*args, **kwargs)
           ^^^^^^^^^^^^^^^^^^^^^^^^^^^
  File "/usr/lib/python3.11/site-packages/MySQLdb/connections.py", line 185, in __init__
    super().__init__(*args, **kwargs2)
MySQLdb.OperationalError: (1045, "Access denied for user 'hbnb_test'@'localhost' (using password: YES)")

The above exception was the direct cause of the following exception:

Traceback (most recent call last):
  File "/usr/lib/python3.11/unittest/loader.py", line 419, in _find_test_path
    module = self._get_module_from_name(name)
             ^^^^^^^^^^^^^^^^^^^^^^^^^^^^^^^^
  File "/usr/lib/python3.11/unittest/loader.py", line 362, in _get_module_from_name
    __import__(name)
  File "/home/meta-bay/workspace/AirB self.dbapi.connect(*cargs, **cparams)
           ^^^^^^^^^^^^^^^^^^^^^^^^^^^^^^^^^^^^^
  File "/usr/lib/python3.11/site-packages/MySQLdb/__init__.py", line 123, in Connect
    return Connection(*args, **kwargs)
           ^^^^^^^^^^^^^^^^^^^^^^^^^^^
  File "/usr/lib/python3.11/site-packages/MySQLdb/connections.py", line 185, in __init__
    super().__init__(*args, **kwargs2)
sqlalchemy.exc.OperationalError: (MySQLdb.OperationalError) (1045, "Access denied for user 'hbnb_test'@'localhost' (using password: YES)")
(Background on this error at: https://sqlalche.me/e/14/e3q8)


======================================================================
ERROR: test_models.test_place (unittest.loader._FailedTest.test_models.test_place)
----------------------------------------------------------------------
ImportError: Failed to import test module: test_models.test_place
Traceback (most recent call last):
  File "/usr/lib/python3.11/site-packages/sqlalchemy/engine/base.py", line 3361, in _wrap_pool_connect
    return fn()
           ^^^^
  File "/usr/lib/python3.11/site-packages/sqlalchemy/pool/base.py", line 325, in connect
    return _ConnectionFairy._checkout(self)
           ^^^^^^^^^^^^^^^^^^^^^^^^^^^^^^^^
  File "/usr/lib/python3.11/site-packages/sqlalchemy/pool/base.py", line 888, in _checkout
    fairy = _ConnectionRecord.checkout(pool)
            ^^^^^^^^^^^^^^^^^^^^^^^^^^^^^^^^
  File "/usr/lib/python3.11/site-packages/sqlalchemy/pool/base.py", line 491, in checkout
    rec = pool._do_get()
          ^^^^^^^^^^^^^^
  File "/usr/lib/python3.11/site-packages/sqlalchemy/pool/impl.py", line 145, in _do_get
    with util.safe_reraise():
  File "/usr/lib/python3.11/site-packages/sqlalchemy/util/langhelpers.py", line 70, in __exit__
    compat.raise_(
  File "/usr/lib/python3.11/site-packages/sqlalchemy/util/compat.py", line 210, in raise_
    raise exception
  File "/usr/lib/python3.11/site-packages/sqlalchemy/pool/impl.py", line 143, in _do_get
    return self._create_connection()
           ^^^^^^^^^^^^^^^^^^^^^^^^^
  File "/usr/lib/python3.11/site-packages/sqlalchemy/pool/base.py", line 271, in _create_connection
    return _ConnectionRecord(self)
           ^^^^^^^^^^^^^^^^^^^^^^^
  File "/usr/lib/python3.11/site-packages/sqlalchemy/pool/base.py", line 386, in __init__
    self.__connect()
  File "/usr/lib/python3.11/site-packages/sqlalchemy/pool/base.py", line 684, in __connect
    with util.safe_reraise():
  File "/usr/lib/python3.11/site-packages/sqlalchemy/util/langhelpers.py", line 70, in __exit__
    compat.raise_(
  File "/usr/lib/python3.11/site-packages/sqlalchemy/util/compat.py", line 210, in raise_
    raise exception
  File "/usr/lib/python3.11/site-packages/sqlalchemy/pool/base.py", line 680, in __connect
    self.dbapi_connection = connection = pool._invoke_creator(self)
                                         ^^^^^^^^^^^^^^^^^^^^^^^^^^
  File "/usr/lib/python3.11/site-packages/sqlalchemy/engine/create.py", line 578, in connect
    return dialect.connect(*cargs, **cparams)
           ^^^^^^^^^^^^^^^^^^^^^^^^^^^^^^^^^^
  File "/usr/lib/python3.11/site-packages/sqlalchemy/engine/default.py", line 598, in connect
    return self.dbapi.connect(*cargs, **cparams)
           ^^^^^^^^^^^^^^^^^^^^^^^^^^^^^^^^^^^^^
  File "/usr/lib/python3.11/site-packages/MySQLdb/__init__.py", line 123, in Connect
    return Connection(*args, **kwargs)
           ^^^^^^^^^^^^^^^^^^^^^^^^^^^
  File "/usr/lib/python3.11/site-packages/MySQLdb/connections.py", line 185, in __init__
    super().__init__(*args, **kwargs2)
MySQLdb.OperationalError: (1045, "Access denied for user 'hbnb_test'@'localhost' (using password: YES)")

The above exception was the direct cause of the following exception:

Traceback (most recent call last):
  File "/usr/lib/python3.11/unittest/loader.py", line 419, in _find_test_path
    module = self._get_module_from_name(name)
             ^^^^^^^^^^^^^^^^^^^^^^^^^^^^^^^^
  File "/usr/lib/python3.11/unittest/loader.py", line 362, in _get_module_from_name
    __import__(name)
  File "/home/meta-bay/workspace/AirBnB_clone_v3/tests/test_models/test_place.py", line 8, in <module>
    import models
  File "/home/meta-bay/workspace/AirBnB_clone_v3/models/__init__.py", line 13, in <module>
    storage = DBStorage()
              ^^^^^^^^^^^
  File "/home/meta-bay/workspace/AirBnB_clone_v3/models/engine/db_storage.py", line 41, in __init__
    Base.metadata.drop_all(self.__engine)
  File "/usr/lib/python3.11/site-packages/sqlalchemy/sql/schema.py", line 4959, in drop_all
    bind._run_ddl_visitor(
  File "/usr/lib/python3.11/site-packages/sqlalchemy/engine/base.py", line 3227, in _run_ddl_visitor
    with self.begin() as conn:
         ^^^^^^^^^^^^
  File "/usr/lib/python3.11/site-packages/sqlalchemy/engine/base.py", line 3143, in begin
    conn = self.connect(close_with_result=close_with_result)
           ^^^^^^^^^^^^^^^^^^^^^^^^^^^^^^^^^^^^^^^^^^^^^^^^^
  File "/usr/lib/python3.11/site-packages/sqlalchemy/engine/base.py", line 3315, in connect
    return self._connection_cls(self, close_with_result=close_with_result)
           ^^^^^^^^^^^^^^^^^^^^^^^^^^^^^^^^^^^^^^^^^^^^^^^^^^^^^^^^^^^^^^^
  File "/usr/lib/python3.11/site-packages/sqlalchemy/engine/base.py", line 96, in __init__
    else engine.raw_connection()
         ^^^^^^^^^^^^^^^^^^^^^^^
  File "/usr/lib/python3.11/site-packages/sqlalchemy/engine/base.py", line 3394, in raw_connection
    return self._wrap_pool_connect(self.pool.connect, _connection)
           ^^^^^^^^^^^^^^^^^^^^^^^^^^^^^^^^^^^^^^^^^^^^^^^^^^^^^^^
  File "/usr/lib/python3.11/site-packages/sqlalchemy/engine/base.py", line 3364, in _wrap_pool_connect
    Connection._handle_dbapi_exception_noconnection(
  File "/usr/lib/python3.11/site-packages/sqlalchemy/engine/base.py", line 2198, in _handle_dbapi_exception_noconnection
    util.raise_(
  File "/usr/lib/python3.11/site-packages/sqlalchemy/util/compat.py", line 210, in raise_
    raise exception
  File "/usr/lib/python3.11/site-packages/sqlalchemy/engine/base.py", line 3361, in _wrap_pool_connect
    return fn()
           ^^^^
  File "/usr/lib/python3.11/site-packages/sqlalchemy/pool/base.py", line 325, in connect
    return _ConnectionFairy._checkout(self)
           ^^^^^^^^^^^^^^^^^^^^^^^^^^^^^^^^
  File "/usr/lib/python3.11/site-packages/sqlalchemy/pool/base.py", line 888, in _checkout
    fairy = _ConnectionRecord.checkout(pool)
            ^^^^^^^^^^^^^^^^^^^^^^^^^^^^^^^^
  File "/usr/lib/python3.11/site-packages/sqlalchemy/pool/base.py", line 491, in checkout
    rec = pool._do_get()
          ^^^^^^^^^^^^^^
  File "/usr/lib/python3.11/site-packages/sqlalchemy/pool/impl.py", line 145, in _do_get
    with util.safe_reraise():
  File "/usr/lib/python3.11/site-packages/sqlalchemy/util/langhelpers.py", line 70, in __exit__
    compat.raise_(
  File "/usr/lib/python3.11/site-packages/sqlalchemy/util/compat.py", line 210, in raise_
    raise exception
  File "/usr/lib/python3.11/site-packages/sqlalchemy/pool/impl.py", line 143, in _do_get
    return self._create_connection()
           ^^^^^^^^^^^^^^^^^^^^^^^^^
  File "/usr/lib/python3.11/site-packages/sqlalchemy/pool/base.py", line 271, in _create_connection
    return _ConnectionRecord(self)
           ^^^^^^^^^^^^^^^^^^^^^^^
  File "/usr/lib/python3.11/site-packages/sqlalchemy/pool/base.py", line 386, in __init__
    self.__connect()
  File "/usr/lib/python3.11/site-packages/sqlalchemy/pool/base.py", line 684, in __connect
    with util.safe_reraise():
  File "/usr/lib/python3.11/site-packages/sqlalchemy/util/langhelpers.py", line 70, in __exit__
    compat.raise_(
  File "/usr/lib/python3.11/site-packages/sqlalchemy/util/compat.py", line 210, in raise_
    raise exception
  File "/usr/lib/python3.11/site-packages/sqlalchemy/pool/base.py", line 680, in __connect
    self.dbapi_connection = connection = pool._invoke_creator(self)
                                         ^^^^^^^^^^^^^^^^^^^^^^^^^^
  File "/usr/lib/python3.11/site-packages/sqlalchemy/engine/create.py", line 578, in connect
    return dialect.connect(*cargs, **cparams)
           ^^^^^^^^^^^^^^^^^^^^^^^^^^^^^^^^^^
  File "/usr/lib/pythonnB_clone_v3/tests/test_models/test_place.py", line 8, in <module>
    import models
  File "/home/meta-bay/workspace/AirBnB_clone_v3/models/__init__.py", line 13, in <module>
    storage = DBStorage()
              ^^^^^^^^^^^
  File "/home/meta-bay/workspace/AirBnB_clone_v3/models/engine/db_storage.py", line 41, in __init__
    Base.metadata.drop_all(self.__engine)
  File "/usr/lib/python3.11/site-packages/sqlalchemy/sql/schema.py", line 4959, in drop_all
    bind._run_ddl_visitor(
  File "/usr/lib/python3.11/site-packages/sqlalchemy/engine/base.py", line 3227, in _run_ddl_visitor
    with self.begin() as conn:
         ^^^^^^^^^^^^
  File "/usr/lib/python3.11/site-packages/sqlalchemy/engine/base.py", line 3143, in begin
    conn = self.connect(close_with_result=close_with_result)
           ^^^^^^^^^^^^^^^^^^^^^^^^^^^^^^^^^^^^^^^^^^^^^^^^^
  File "/usr/lib/python3.11/site-packages/sqlalchemy/engine/base.py", line 3315, in connect
    return self._connection_cls(self, close_with_result=close_with_result)
           ^^^^^^^^^^^^^^^^^^^^^^^^^^^^^^^^^^^^^^^^^^^^^^^^^^^^^^^^^^^^^^^
  File "/usr/lib/python3.11/site-packages/sqlalchemy/engine/base.py", line 96, in __init__
    else engine.raw_connection()
         ^^^^^^^^^^^^^^^^^^^^^^^
  File "/usr/lib/python3.11/site-packages/sqlalchemy/engine/base.py", line 3394, in raw_connection
    return self._wrap_pool_connect(self.pool.connect, _connection)
           ^^^^^^^^^^^^^^^^^^^^^^^^^^^^^^^^^^^^^^^^^^^^^^^^^^^^^^^
  File "/usr/lib/python3.11/site-packages/sqlalchemy/engine/base.py", line 3364, in _wrap_pool_connect
    Connection._handle_dbapi_exception_noconnection(
  File "/usr/lib/python3.11/site-packages/sqlalchemy/engine/base.py", line 2198, in _handle_dbapi_exception_noconnection
    util.raise_(
  File "/usr/lib/python3.11/site-packages/sqlalchemy/util/compat.py", line 210, in raise_
    raise exception
  File "/usr/lib/python3.11/site-packages/sqlalchemy/engine/base.py", line 3361, in _wrap_pool_connect
    return fn()
           ^^^^
  File "/usr/lib/python3.11/site-packages/sqlalchemy/pool/base.py", line 325, in connect
    return _ConnectionFairy._checkout(self)
           ^^^^^^^^^^^^^^^^^^^^^^^^^^^^^^^^
  File "/usr/lib/python3.11/site-packages/sqlalchemy/pool/base.py", line 888, in _checkout
    fairy = _ConnectionRecord.checkout(pool)
            ^^^^^^^^^^^^^^^^^^^^^^^^^^^^^^^^
  File "/usr/lib/python3.11/site-packages/sqlalchemy/pool/base.py", line 491, in checkout
    rec = pool._do_get()
          ^^^^^^^^^^^^^^
  File "/usr/lib/python3.11/site-packages/sqlalchemy/pool/impl.py", line 145, in _do_get
    with util.safe_reraise():
  File "/usr/lib/python3.11/site-packages/sqlalchemy/util/langhelpers.py", line 70, in __exit__
    compat.raise_(
  File "/usr/lib/python3.11/site-packages/sqlalchemy/util/compat.py", line 210, in raise_
    raise exception
  File "/usr/lib/python3.11/site-packages/sqlalchemy/pool/impl.py", line 143, in _do_get
    return self._create_connection()
           ^^^^^^^^^^^^^^^^^^^^^^^^^
  File "/usr/lib/python3.11/site-packages/sqlalchemy/pool/base.py", line 271, in _create_connection
    return _ConnectionRecord(self)
           ^^^^^^^^^^^^^^^^^^^^^^^
  File "/usr/lib/python3.11/site-packages/sqlalchemy/pool/base.py", line 386, in __init__
    self.__connect()
  File "/usr/lib/python3.11/site-packages/sqlalchemy/pool/base.py", line 684, in __connect
    with util.safe_reraise():
  File "/usr/lib/python3.11/site-packages/sqlalchemy/util/langhelpers.py", line 70, in __exit__
    compat.raise_(
  File "/usr/lib/python3.11/site-packages/sqlalchemy/util/compat.py", line 210, in raise_
    raise exception
  File "/usr/lib/python3.11/site-packages/sqlalchemy/pool/base.py", line 680, in __connect
    self.dbapi_connection = connection = pool._invoke_creator(self)
                                         ^^^^^^^^^^^^^^^^^^^^^^^^^^
  File "/usr/lib/python3.11/site-packages/sqlalchemy/engine/create.py", line 578, in connect
    return dialect.connect(*cargs, **cparams)
           ^^^^^^^^^^^^^^^^^^^^^^^^^^^^^^^^^^
  File "/usr/lib/python3.11/site-packages/sqlalchemy/engine/default.py", line 598, in connect
    return self.dbapi.connect(*cargs, **cparams)
           ^^^^^^^^^^^^^^^^^^^^^^^^^^^^^^^^^^^^^
  File "/usr/lib/python3.11/site-packages/MySQLdb/__init__.py", line 123, in Connect
    return Connection(*args, **kwargs)
           ^^^^^^^^^^^^^^^^^^^^^^^^^^^
  File "/usr/lib/python3.11/site-packages/MySQLdb/connections.py", line 185, in __init__
    super().__init__(*args, **kwargs2)
sqlalchemy.exc.OperationalError: (MySQLdb.OperationalError) (1045, "Access denied for user 'hbnb_test'@'localhost' (using password: YES)")
(Background on this error at: https://sqlalche.me/e/14/e3q8)


======================================================================
ERROR: test_models.test_review (unittest.loader._FailedTest.test_models.test_review)
----------------------------------------------------------------------
ImportError: Failed to import test module: test_models.test_review
Traceback (most recent call last):
  File "/usr/lib/python3.11/site-packages/sqlalchemy/engine/base.py", line 3361, in _wrap_pool_connect
    return fn()
           ^^^^
  File "/usr/lib/python3.11/site-packages/sqlalchemy/pool/base.py", line 325, in connect
    return _ConnectionFairy._checkout(self)
           ^^^^^^^^^^^^^^^^^^^^^^^^^^^^^^^^
  File "/usr/lib/python3.11/site-packages/sqlalchemy/pool/base.py", line 888, in _checkout
    fairy = _ConnectionRecord.checkout(pool)
            ^^^^^^^^^^^^^^^^^^^^^^^^^^^^^^^^
  File "/usr/lib/python3.11/site-packages/sqlalchemy/pool/base.py", line 491, in checkout
    rec = pool._do_get()
          ^^^^^^^^^^^^^^
  File "/usr/lib/python3.11/site-packages/sqlalchemy/pool/impl.py", line 145, in _do_get
    with util.safe_reraise():
  File "/usr/lib/python3.11/site-packages/sqlalchemy/util/langhelpers.py", line 70, in __exit__
    compat.raise_(
  File "/usr/lib/python3.11/site-packages/sqlalchemy/util/compat.py", line 210, in raise_
    raise exception
  File "/usr/lib/python3.11/site-packages/sqlalchemy/pool/impl.py", line 143, in _do_get
    return self._create_connection()
           ^^^^^^^^^^^^^^^^^^^^^^^^^
  File "/usr/lib/python3.11/site-packages/sqlalchemy/pool/base.py", line 271, in _create_connection
    return _ConnectionRecord(self)
           ^^^^^^^^^^^^^^^^^^^^^^^
  File "/usr/lib/python3.11/site-packages/sqlalchemy/pool/base.py", line 386, in __init__
    self.__connect()
  File "/usr/lib/python3.11/site-packages/sqlalchemy/pool/base.py", line 684, in __connect
    with util.safe_reraise():
  File "/usr/lib/python3.11/site-packages/sqlalchemy/util/langhelpers.py", line 70, in __exit__
    compat.raise_(
  File "/usr/lib/python3.11/site-packages/sqlalchemy/util/compat.py", line 210, in raise_
    raise exception
  File "/usr/lib/python3.11/site-packages/sqlalchemy/pool/base.py", line 680, in __connect
    self.dbapi_connection = connection = pool._invoke_creator(self)
                                         ^^^^^^^^^^^^^^^^^^^^^^^^^^
  File "/usr/lib/python3.11/site-packages/sqlalchemy/engine/create.py", line 578, in connect
    return dialect.connect(*cargs, **cparams)
           ^^^^^^^^^^^^^^^^^^^^^^^^^^^^^^^^^^
  File "/usr/lib/python3.11/site-packages/sqlalchemy/engine/default.py", line 598, in connect
    return self.dbapi.connect(*cargs, **cparams)
           ^^^^^^^^^^^^^^^^^^^^^^^^^^^^^^^^^^^^^
  File "/usr/lib/python3.11/site-packages/MySQLdb/__init__.py", line 123, in Connect
    return Connection(*args, **kwargs)
           ^^^^^^^^^^^^^^^^^^^^^^^^^^^
  File "/usr/lib/python3.11/site-packages/MySQLdb/connections.py", line 185, in __init__
    super().__init__(*args, **kwargs2)
MySQLdb.OperationalError: (1045, "Access denied for user 'hbnb_test'@'localhost' (using password: YES)")

The above exception was the direct cause of the following exception:

Traceback (most recent call last):
  File "/usr/lib/python3.11/unittest/loader.py", line 419, in _find_test_path
    module = self._get_module_from_name(name)
             ^^^^^^^^^^^^^^^^^^^^^^^^^^^^^^^^
  File "/usr/lib/python3.11/unittest/loader.py", line 362,3.11/site-packages/sqlalchemy/engine/default.py", line 598, in connect
    return self.dbapi.connect(*cargs, **cparams)
           ^^^^^^^^^^^^^^^^^^^^^^^^^^^^^^^^^^^^^
  File "/usr/lib/python3.11/site-packages/MySQLdb/__init__.py", line 123, in Connect
    return Connection(*args, **kwargs)
           ^^^^^^^^^^^^^^^^^^^^^^^^^^^
  File "/usr/lib/python3.11/site-packages/MySQLdb/connections.py", line 185, in __init__
    super().__init__(*args, **kwargs2)
sqlalchemy.exc.OperationalError: (MySQLdb.OperationalError) (1045, "Access denied for user 'hbnb_test'@'localhost' (using password: YES)")
(Background on this error at: https://sqlalche.me/e/14/e3q8)


======================================================================
ERROR: test_models.test_review (unittest.loader._FailedTest.test_models.test_review)
----------------------------------------------------------------------
ImportError: Failed to import test module: test_models.test_review
Traceback (most recent call last):
  File "/usr/lib/python3.11/site-packages/sqlalchemy/engine/base.py", line 3361, in _wrap_pool_connect
    return fn()
           ^^^^
  File "/usr/lib/python3.11/site-packages/sqlalchemy/pool/base.py", line 325, in connect
    return _ConnectionFairy._checkout(self)
           ^^^^^^^^^^^^^^^^^^^^^^^^^^^^^^^^
  File "/usr/lib/python3.11/site-packages/sqlalchemy/pool/base.py", line 888, in _checkout
    fairy = _ConnectionRecord.checkout(pool)
            ^^^^^^^^^^^^^^^^^^^^^^^^^^^^^^^^
  File "/usr/lib/python3.11/site-packages/sqlalchemy/pool/base.py", line 491, in checkout
    rec = pool._do_get()
          ^^^^^^^^^^^^^^
  File "/usr/lib/python3.11/site-packages/sqlalchemy/pool/impl.py", line 145, in _do_get
    with util.safe_reraise():
  File "/usr/lib/python3.11/site-packages/sqlalchemy/util/langhelpers.py", line 70, in __exit__
    compat.raise_(
  File "/usr/lib/python3.11/site-packages/sqlalchemy/util/compat.py", line 210, in raise_
    raise exception
  File "/usr/lib/python3.11/site-packages/sqlalchemy/pool/impl.py", line 143, in _do_get
    return self._create_connection()
           ^^^^^^^^^^^^^^^^^^^^^^^^^
  File "/usr/lib/python3.11/site-packages/sqlalchemy/pool/base.py", line 271, in _create_connection
    return _ConnectionRecord(self)
           ^^^^^^^^^^^^^^^^^^^^^^^
  File "/usr/lib/python3.11/site-packages/sqlalchemy/pool/base.py", line 386, in __init__
    self.__connect()
  File "/usr/lib/python3.11/site-packages/sqlalchemy/pool/base.py", line 684, in __connect
    with util.safe_reraise():
  File "/usr/lib/python3.11/site-packages/sqlalchemy/util/langhelpers.py", line 70, in __exit__
    compat.raise_(
  File "/usr/lib/python3.11/site-packages/sqlalchemy/util/compat.py", line 210, in raise_
    raise exception
  File "/usr/lib/python3.11/site-packages/sqlalchemy/pool/base.py", line 680, in __connect
    self.dbapi_connection = connection = pool._invoke_creator(self)
                                         ^^^^^^^^^^^^^^^^^^^^^^^^^^
  File "/usr/lib/python3.11/site-packages/sqlalchemy/engine/create.py", line 578, in connect
    return dialect.connect(*cargs, **cparams)
           ^^^^^^^^^^^^^^^^^^^^^^^^^^^^^^^^^^
  File "/usr/lib/python3.11/site-packages/sqlalchemy/engine/default.py", line 598, in connect
    return self.dbapi.connect(*cargs, **cparams)
           ^^^^^^^^^^^^^^^^^^^^^^^^^^^^^^^^^^^^^
  File "/usr/lib/python3.11/site-packages/MySQLdb/__init__.py", line 123, in Connect
    return Connection(*args, **kwargs)
           ^^^^^^^^^^^^^^^^^^^^^^^^^^^
  File "/usr/lib/python3.11/site-packages/MySQLdb/connections.py", line 185, in __init__
    super().__init__(*args, **kwargs2)
MySQLdb.OperationalError: (1045, "Access denied for user 'hbnb_test'@'localhost' (using password: YES)")

The above exception was the direct cause of the following exception:

Traceback (most recent call last):
  File "/usr/lib/python3.11/unittest/loader.py", line 419, in _find_test_path
    module = self._get_module_from_name(name)
             ^^^^^^^^^^^^^^^^^^^^^^^^^^^^^^^^
  File "/usr/lib/python3.11/unittest/loader.py", line 362, in _get_module_from_name
    __import__(name)
  File "/home/meta-bay/workspace/AirBnB_clone_v3/tests/test_models/test_review.py", line 8, in <module>
    import models
  File "/home/meta-bay/workspace/AirBnB_clone_v3/models/__init__.py", line 13, in <module>
    storage = DBStorage()
              ^^^^^^^^^^^
  File "/home/meta-bay/workspace/AirBnB_clone_v3/models/engine/db_storage.py", line 41, in __init__
    Base.metadata.drop_all(self.__engine)
  File "/usr/lib/python3.11/site-packages/sqlalchemy/sql/schema.py", line 4959, in drop_all
    bind._run_ddl_visitor(
  File "/usr/lib/python3.11/site-packages/sqlalchemy/engine/base.py", line 3227, in _run_ddl_visitor
    with self.begin() as conn:
         ^^^^^^^^^^^^
  File "/usr/lib/python3.11/site-packages/sqlalchemy/engine/base.py", line 3143, in begin
    conn = self.connect(close_with_result=close_with_result)
           ^^^^^^^^^^^^^^^^^^^^^^^^^^^^^^^^^^^^^^^^^^^^^^^^^
  File "/usr/lib/python3.11/site-packages/sqlalchemy/engine/base.py", line 3315, in connect
    return self._connection_cls(self, close_with_result=close_with_result)
           ^^^^^^^^^^^^^^^^^^^^^^^^^^^^^^^^^^^^^^^^^^^^^^^^^^^^^^^^^^^^^^^
  File "/usr/lib/python3.11/site-packages/sqlalchemy/engine/base.py", line 96, in __init__
    else engine.raw_connection()
         ^^^^^^^^^^^^^^^^^^^^^^^
  File "/usr/lib/python3.11/site-packages/sqlalchemy/engine/base.py", line 3394, in raw_connection
    return self._wrap_pool_connect(self.pool.connect, _connection)
           ^^^^^^^^^^^^^^^^^^^^^^^^^^^^^^^^^^^^^^^^^^^^^^^^^^^^^^^
  File "/usr/lib/python3.11/site-packages/sqlalchemy/engine/base.py", line 3364, in _wrap_pool_connect
    Connection._handle_dbapi_exception_noconnection(
  File "/usr/lib/python3.11/site-packages/sqlalchemy/engine/base.py", line 2198, in _handle_dbapi_exception_noconnection
    util.raise_(
  File "/usr/lib/python3.11/site-packages/sqlalchemy/util/compat.py", line 210, in raise_
    raise exception
  File "/usr/lib/python3.11/site-packages/sqlalchemy/engine/base.py", line 3361, in _wrap_pool_connect
    return fn()
           ^^^^
  File "/usr/lib/python3.11/site-packages/sqlalchemy/pool/base.py", line 325, in connect
    return _ConnectionFairy._checkout(self)
           ^^^^^^^^^^^^^^^^^^^^^^^^^^^^^^^^
  File "/usr/lib/python3.11/site-packages/sqlalchemy/pool/base.py", line 888, in _checkout
    fairy = _ConnectionRecord.checkout(pool)
            ^^^^^^^^^^^^^^^^^^^^^^^^^^^^^^^^
  File "/usr/lib/python3.11/site-packages/sqlalchemy/pool/base.py", line 491, in checkout
    rec = pool._do_get()
          ^^^^^^^^^^^^^^
  File "/usr/lib/python3.11/site-packages/sqlalchemy/pool/impl.py", line 145, in _do_get
    with util.safe_reraise():
  File "/usr/lib/python3.11/site-packages/sqlalchemy/util/langhelpers.py", line 70, in __exit__
    compat.raise_(
  File "/usr/lib/python3.11/site-packages/sqlalchemy/util/compat.py", line 210, in raise_
    raise exception
  File "/usr/lib/python3.11/site-packages/sqlalchemy/pool/impl.py", line 143, in _do_get
    return self._create_connection()
           ^^^^^^^^^^^^^^^^^^^^^^^^^
  File "/usr/lib/python3.11/site-packages/sqlalchemy/pool/base.py", line 271, in _create_connection
    return _ConnectionRecord(self)
           ^^^^^^^^^^^^^^^^^^^^^^^
  File "/usr/lib/python3.11/site-packages/sqlalchemy/pool/base.py", line 386, in __init__
    self.__connect()
  File "/usr/lib/python3.11/site-packages/sqlalchemy/pool/base.py", line 684, in __connect
    with util.safe_reraise():
  File "/usr/lib/python3.11/site-packages/sqlalchemy/util/langhelpers.py", line 70, in __exit__
    compat.raise_(
  File "/usr/lib/python3.11/site-packages/sqlalchemy/util/compat.py", line 210, in raise_
    raise exception
  File "/usr/lib/python3.11/site-packages/sqlalchemy/pool/base.py", line 680, in __connect
    self.dbapi_connection = connection = pool._invoke_creator(self)
                                         ^^^^^^^^^^^^^^^^^^^^^^^^^^
  File "/usr/lib/python3.11/site-packages/sqlalchemy/engine/create.py", line 578, in connect
    return dialect.connect(*ca in _get_module_from_name
    __import__(name)
  File "/home/meta-bay/workspace/AirBnB_clone_v3/tests/test_models/test_review.py", line 8, in <module>
    import models
  File "/home/meta-bay/workspace/AirBnB_clone_v3/models/__init__.py", line 13, in <module>
    storage = DBStorage()
              ^^^^^^^^^^^
  File "/home/meta-bay/workspace/AirBnB_clone_v3/models/engine/db_storage.py", line 41, in __init__
    Base.metadata.drop_all(self.__engine)
  File "/usr/lib/python3.11/site-packages/sqlalchemy/sql/schema.py", line 4959, in drop_all
    bind._run_ddl_visitor(
  File "/usr/lib/python3.11/site-packages/sqlalchemy/engine/base.py", line 3227, in _run_ddl_visitor
    with self.begin() as conn:
         ^^^^^^^^^^^^
  File "/usr/lib/python3.11/site-packages/sqlalchemy/engine/base.py", line 3143, in begin
    conn = self.connect(close_with_result=close_with_result)
           ^^^^^^^^^^^^^^^^^^^^^^^^^^^^^^^^^^^^^^^^^^^^^^^^^
  File "/usr/lib/python3.11/site-packages/sqlalchemy/engine/base.py", line 3315, in connect
    return self._connection_cls(self, close_with_result=close_with_result)
           ^^^^^^^^^^^^^^^^^^^^^^^^^^^^^^^^^^^^^^^^^^^^^^^^^^^^^^^^^^^^^^^
  File "/usr/lib/python3.11/site-packages/sqlalchemy/engine/base.py", line 96, in __init__
    else engine.raw_connection()
         ^^^^^^^^^^^^^^^^^^^^^^^
  File "/usr/lib/python3.11/site-packages/sqlalchemy/engine/base.py", line 3394, in raw_connection
    return self._wrap_pool_connect(self.pool.connect, _connection)
           ^^^^^^^^^^^^^^^^^^^^^^^^^^^^^^^^^^^^^^^^^^^^^^^^^^^^^^^
  File "/usr/lib/python3.11/site-packages/sqlalchemy/engine/base.py", line 3364, in _wrap_pool_connect
    Connection._handle_dbapi_exception_noconnection(
  File "/usr/lib/python3.11/site-packages/sqlalchemy/engine/base.py", line 2198, in _handle_dbapi_exception_noconnection
    util.raise_(
  File "/usr/lib/python3.11/site-packages/sqlalchemy/util/compat.py", line 210, in raise_
    raise exception
  File "/usr/lib/python3.11/site-packages/sqlalchemy/engine/base.py", line 3361, in _wrap_pool_connect
    return fn()
           ^^^^
  File "/usr/lib/python3.11/site-packages/sqlalchemy/pool/base.py", line 325, in connect
    return _ConnectionFairy._checkout(self)
           ^^^^^^^^^^^^^^^^^^^^^^^^^^^^^^^^
  File "/usr/lib/python3.11/site-packages/sqlalchemy/pool/base.py", line 888, in _checkout
    fairy = _ConnectionRecord.checkout(pool)
            ^^^^^^^^^^^^^^^^^^^^^^^^^^^^^^^^
  File "/usr/lib/python3.11/site-packages/sqlalchemy/pool/base.py", line 491, in checkout
    rec = pool._do_get()
          ^^^^^^^^^^^^^^
  File "/usr/lib/python3.11/site-packages/sqlalchemy/pool/impl.py", line 145, in _do_get
    with util.safe_reraise():
  File "/usr/lib/python3.11/site-packages/sqlalchemy/util/langhelpers.py", line 70, in __exit__
    compat.raise_(
  File "/usr/lib/python3.11/site-packages/sqlalchemy/util/compat.py", line 210, in raise_
    raise exception
  File "/usr/lib/python3.11/site-packages/sqlalchemy/pool/impl.py", line 143, in _do_get
    return self._create_connection()
           ^^^^^^^^^^^^^^^^^^^^^^^^^
  File "/usr/lib/python3.11/site-packages/sqlalchemy/pool/base.py", line 271, in _create_connection
    return _ConnectionRecord(self)
           ^^^^^^^^^^^^^^^^^^^^^^^
  File "/usr/lib/python3.11/site-packages/sqlalchemy/pool/base.py", line 386, in __init__
    self.__connect()
  File "/usr/lib/python3.11/site-packages/sqlalchemy/pool/base.py", line 684, in __connect
    with util.safe_reraise():
  File "/usr/lib/python3.11/site-packages/sqlalchemy/util/langhelpers.py", line 70, in __exit__
    compat.raise_(
  File "/usr/lib/python3.11/site-packages/sqlalchemy/util/compat.py", line 210, in raise_
    raise exception
  File "/usr/lib/python3.11/site-packages/sqlalchemy/pool/base.py", line 680, in __connect
    self.dbapi_connection = connection = pool._invoke_creator(self)
                                         ^^^^^^^^^^^^^^^^^^^^^^^^^^
  File "/usr/lib/python3.11/site-packages/sqlalchemy/engine/create.py", line 578, in connect
    return dialect.connect(*cargs, **cparams)
           ^^^^^^^^^^^^^^^^^^^^^^^^^^^^^^^^^^
  File "/usr/lib/python3.11/site-packages/sqlalchemy/engine/default.py", line 598, in connect
    return self.dbapi.connect(*cargs, **cparams)
           ^^^^^^^^^^^^^^^^^^^^^^^^^^^^^^^^^^^^^
  File "/usr/lib/python3.11/site-packages/MySQLdb/__init__.py", line 123, in Connect
    return Connection(*args, **kwargs)
           ^^^^^^^^^^^^^^^^^^^^^^^^^^^
  File "/usr/lib/python3.11/site-packages/MySQLdb/connections.py", line 185, in __init__
    super().__init__(*args, **kwargs2)
sqlalchemy.exc.OperationalError: (MySQLdb.OperationalError) (1045, "Access denied for user 'hbnb_test'@'localhost' (using password: YES)")
(Background on this error at: https://sqlalche.me/e/14/e3q8)


======================================================================
ERROR: test_models.test_state (unittest.loader._FailedTest.test_models.test_state)
----------------------------------------------------------------------
ImportError: Failed to import test module: test_models.test_state
Traceback (most recent call last):
  File "/usr/lib/python3.11/site-packages/sqlalchemy/engine/base.py", line 3361, in _wrap_pool_connect
    return fn()
           ^^^^
  File "/usr/lib/python3.11/site-packages/sqlalchemy/pool/base.py", line 325, in connect
    return _ConnectionFairy._checkout(self)
           ^^^^^^^^^^^^^^^^^^^^^^^^^^^^^^^^
  File "/usr/lib/python3.11/site-packages/sqlalchemy/pool/base.py", line 888, in _checkout
    fairy = _ConnectionRecord.checkout(pool)
            ^^^^^^^^^^^^^^^^^^^^^^^^^^^^^^^^
  File "/usr/lib/python3.11/site-packages/sqlalchemy/pool/base.py", line 491, in checkout
    rec = pool._do_get()
          ^^^^^^^^^^^^^^
  File "/usr/lib/python3.11/site-packages/sqlalchemy/pool/impl.py", line 145, in _do_get
    with util.safe_reraise():
  File "/usr/lib/python3.11/site-packages/sqlalchemy/util/langhelpers.py", line 70, in __exit__
    compat.raise_(
  File "/usr/lib/python3.11/site-packages/sqlalchemy/util/compat.py", line 210, in raise_
    raise exception
  File "/usr/lib/python3.11/site-packages/sqlalchemy/pool/impl.py", line 143, in _do_get
    return self._create_connection()
           ^^^^^^^^^^^^^^^^^^^^^^^^^
  File "/usr/lib/python3.11/site-packages/sqlalchemy/pool/base.py", line 271, in _create_connection
    return _ConnectionRecord(self)
           ^^^^^^^^^^^^^^^^^^^^^^^
  File "/usr/lib/python3.11/site-packages/sqlalchemy/pool/base.py", line 386, in __init__
    self.__connect()
  File "/usr/lib/python3.11/site-packages/sqlalchemy/pool/base.py", line 684, in __connect
    with util.safe_reraise():
  File "/usr/lib/python3.11/site-packages/sqlalchemy/util/langhelpers.py", line 70, in __exit__
    compat.raise_(
  File "/usr/lib/python3.11/site-packages/sqlalchemy/util/compat.py", line 210, in raise_
    raise exception
  File "/usr/lib/python3.11/site-packages/sqlalchemy/pool/base.py", line 680, in __connect
    self.dbapi_connection = connection = pool._invoke_creator(self)
                                         ^^^^^^^^^^^^^^^^^^^^^^^^^^
  File "/usr/lib/python3.11/site-packages/sqlalchemy/engine/create.py", line 578, in connect
    return dialect.connect(*cargs, **cparams)
           ^^^^^^^^^^^^^^^^^^^^^^^^^^^^^^^^^^
  File "/usr/lib/python3.11/site-packages/sqlalchemy/engine/default.py", line 598, in connect
    return self.dbapi.connect(*cargs, **cparams)
           ^^^^^^^^^^^^^^^^^^^^^^^^^^^^^^^^^^^^^
  File "/usr/lib/python3.11/site-packages/MySQLdb/__init__.py", line 123, in Connect
    return Connection(*args, **kwargs)
           ^^^^^^^^^^^^^^^^^^^^^^^^^^^
  File "/usr/lib/python3.11/site-packages/MySQLdb/connections.py", line 185, in __init__
    super().__init__(*args, **kwargs2)
MySQLdb.OperationalError: (1045, "Access denied for user 'hbnb_test'@'localhost' (using password: YES)")

The above exception was the direct cause of the following exception:

Traceback (most recent call last):
  File "/usr/lib/python3.11/unittest/loader.py", line 419, in _find_test_path
    module = self._get_module_from_name(name)
             ^^^^^^^^^rgs, **cparams)
           ^^^^^^^^^^^^^^^^^^^^^^^^^^^^^^^^^^
  File "/usr/lib/python3.11/site-packages/sqlalchemy/engine/default.py", line 598, in connect
    return self.dbapi.connect(*cargs, **cparams)
           ^^^^^^^^^^^^^^^^^^^^^^^^^^^^^^^^^^^^^
  File "/usr/lib/python3.11/site-packages/MySQLdb/__init__.py", line 123, in Connect
    return Connection(*args, **kwargs)
           ^^^^^^^^^^^^^^^^^^^^^^^^^^^
  File "/usr/lib/python3.11/site-packages/MySQLdb/connections.py", line 185, in __init__
    super().__init__(*args, **kwargs2)
sqlalchemy.exc.OperationalError: (MySQLdb.OperationalError) (1045, "Access denied for user 'hbnb_test'@'localhost' (using password: YES)")
(Background on this error at: https://sqlalche.me/e/14/e3q8)


======================================================================
ERROR: test_models.test_state (unittest.loader._FailedTest.test_models.test_state)
----------------------------------------------------------------------
ImportError: Failed to import test module: test_models.test_state
Traceback (most recent call last):
  File "/usr/lib/python3.11/site-packages/sqlalchemy/engine/base.py", line 3361, in _wrap_pool_connect
    return fn()
           ^^^^
  File "/usr/lib/python3.11/site-packages/sqlalchemy/pool/base.py", line 325, in connect
    return _ConnectionFairy._checkout(self)
           ^^^^^^^^^^^^^^^^^^^^^^^^^^^^^^^^
  File "/usr/lib/python3.11/site-packages/sqlalchemy/pool/base.py", line 888, in _checkout
    fairy = _ConnectionRecord.checkout(pool)
            ^^^^^^^^^^^^^^^^^^^^^^^^^^^^^^^^
  File "/usr/lib/python3.11/site-packages/sqlalchemy/pool/base.py", line 491, in checkout
    rec = pool._do_get()
          ^^^^^^^^^^^^^^
  File "/usr/lib/python3.11/site-packages/sqlalchemy/pool/impl.py", line 145, in _do_get
    with util.safe_reraise():
  File "/usr/lib/python3.11/site-packages/sqlalchemy/util/langhelpers.py", line 70, in __exit__
    compat.raise_(
  File "/usr/lib/python3.11/site-packages/sqlalchemy/util/compat.py", line 210, in raise_
    raise exception
  File "/usr/lib/python3.11/site-packages/sqlalchemy/pool/impl.py", line 143, in _do_get
    return self._create_connection()
           ^^^^^^^^^^^^^^^^^^^^^^^^^
  File "/usr/lib/python3.11/site-packages/sqlalchemy/pool/base.py", line 271, in _create_connection
    return _ConnectionRecord(self)
           ^^^^^^^^^^^^^^^^^^^^^^^
  File "/usr/lib/python3.11/site-packages/sqlalchemy/pool/base.py", line 386, in __init__
    self.__connect()
  File "/usr/lib/python3.11/site-packages/sqlalchemy/pool/base.py", line 684, in __connect
    with util.safe_reraise():
  File "/usr/lib/python3.11/site-packages/sqlalchemy/util/langhelpers.py", line 70, in __exit__
    compat.raise_(
  File "/usr/lib/python3.11/site-packages/sqlalchemy/util/compat.py", line 210, in raise_
    raise exception
  File "/usr/lib/python3.11/site-packages/sqlalchemy/pool/base.py", line 680, in __connect
    self.dbapi_connection = connection = pool._invoke_creator(self)
                                         ^^^^^^^^^^^^^^^^^^^^^^^^^^
  File "/usr/lib/python3.11/site-packages/sqlalchemy/engine/create.py", line 578, in connect
    return dialect.connect(*cargs, **cparams)
           ^^^^^^^^^^^^^^^^^^^^^^^^^^^^^^^^^^
  File "/usr/lib/python3.11/site-packages/sqlalchemy/engine/default.py", line 598, in connect
    return self.dbapi.connect(*cargs, **cparams)
           ^^^^^^^^^^^^^^^^^^^^^^^^^^^^^^^^^^^^^
  File "/usr/lib/python3.11/site-packages/MySQLdb/__init__.py", line 123, in Connect
    return Connection(*args, **kwargs)
           ^^^^^^^^^^^^^^^^^^^^^^^^^^^
  File "/usr/lib/python3.11/site-packages/MySQLdb/connections.py", line 185, in __init__
    super().__init__(*args, **kwargs2)
MySQLdb.OperationalError: (1045, "Access denied for user 'hbnb_test'@'localhost' (using password: YES)")

The above exception was the direct cause of the following exception:

Traceback (most recent call last):
  File "/usr/lib/python3.11/unittest/loader.py", line 419, in _find_test_path
    module = self._get_module_from_name(name)
             ^^^^^^^^^^^^^^^^^^^^^^^^^^^^^^^^
  File "/usr/lib/python3.11/unittest/loader.py", line 362, in _get_module_from_name
    __import__(name)
  File "/home/meta-bay/workspace/AirBnB_clone_v3/tests/test_models/test_state.py", line 8, in <module>
    import models
  File "/home/meta-bay/workspace/AirBnB_clone_v3/models/__init__.py", line 13, in <module>
    storage = DBStorage()
              ^^^^^^^^^^^
  File "/home/meta-bay/workspace/AirBnB_clone_v3/models/engine/db_storage.py", line 41, in __init__
    Base.metadata.drop_all(self.__engine)
  File "/usr/lib/python3.11/site-packages/sqlalchemy/sql/schema.py", line 4959, in drop_all
    bind._run_ddl_visitor(
  File "/usr/lib/python3.11/site-packages/sqlalchemy/engine/base.py", line 3227, in _run_ddl_visitor
    with self.begin() as conn:
         ^^^^^^^^^^^^
  File "/usr/lib/python3.11/site-packages/sqlalchemy/engine/base.py", line 3143, in begin
    conn = self.connect(close_with_result=close_with_result)
           ^^^^^^^^^^^^^^^^^^^^^^^^^^^^^^^^^^^^^^^^^^^^^^^^^
  File "/usr/lib/python3.11/site-packages/sqlalchemy/engine/base.py", line 3315, in connect
    return self._connection_cls(self, close_with_result=close_with_result)
           ^^^^^^^^^^^^^^^^^^^^^^^^^^^^^^^^^^^^^^^^^^^^^^^^^^^^^^^^^^^^^^^
  File "/usr/lib/python3.11/site-packages/sqlalchemy/engine/base.py", line 96, in __init__
    else engine.raw_connection()
         ^^^^^^^^^^^^^^^^^^^^^^^
  File "/usr/lib/python3.11/site-packages/sqlalchemy/engine/base.py", line 3394, in raw_connection
    return self._wrap_pool_connect(self.pool.connect, _connection)
           ^^^^^^^^^^^^^^^^^^^^^^^^^^^^^^^^^^^^^^^^^^^^^^^^^^^^^^^
  File "/usr/lib/python3.11/site-packages/sqlalchemy/engine/base.py", line 3364, in _wrap_pool_connect
    Connection._handle_dbapi_exception_noconnection(
  File "/usr/lib/python3.11/site-packages/sqlalchemy/engine/base.py", line 2198, in _handle_dbapi_exception_noconnection
    util.raise_(
  File "/usr/lib/python3.11/site-packages/sqlalchemy/util/compat.py", line 210, in raise_
    raise exception
  File "/usr/lib/python3.11/site-packages/sqlalchemy/engine/base.py", line 3361, in _wrap_pool_connect
    return fn()
           ^^^^
  File "/usr/lib/python3.11/site-packages/sqlalchemy/pool/base.py", line 325, in connect
    return _ConnectionFairy._checkout(self)
           ^^^^^^^^^^^^^^^^^^^^^^^^^^^^^^^^
  File "/usr/lib/python3.11/site-packages/sqlalchemy/pool/base.py", line 888, in _checkout
    fairy = _ConnectionRecord.checkout(pool)
            ^^^^^^^^^^^^^^^^^^^^^^^^^^^^^^^^
  File "/usr/lib/python3.11/site-packages/sqlalchemy/pool/base.py", line 491, in checkout
    rec = pool._do_get()
          ^^^^^^^^^^^^^^
  File "/usr/lib/python3.11/site-packages/sqlalchemy/pool/impl.py", line 145, in _do_get
    with util.safe_reraise():
  File "/usr/lib/python3.11/site-packages/sqlalchemy/util/langhelpers.py", line 70, in __exit__
    compat.raise_(
  File "/usr/lib/python3.11/site-packages/sqlalchemy/util/compat.py", line 210, in raise_
    raise exception
  File "/usr/lib/python3.11/site-packages/sqlalchemy/pool/impl.py", line 143, in _do_get
    return self._create_connection()
           ^^^^^^^^^^^^^^^^^^^^^^^^^
  File "/usr/lib/python3.11/site-packages/sqlalchemy/pool/base.py", line 271, in _create_connection
    return _ConnectionRecord(self)
           ^^^^^^^^^^^^^^^^^^^^^^^
  File "/usr/lib/python3.11/site-packages/sqlalchemy/pool/base.py", line 386, in __init__
    self.__connect()
  File "/usr/lib/python3.11/site-packages/sqlalchemy/pool/base.py", line 684, in __connect
    with util.safe_reraise():
  File "/usr/lib/python3.11/site-packages/sqlalchemy/util/langhelpers.py", line 70, in __exit__
    compat.raise_(
  File "/usr/lib/python3.11/site-packages/sqlalchemy/util/compat.py", line 210, in raise_
    raise exception
  File "/usr/lib/python3.11/site-packages/sqlalchemy/pool/base.py", line 680, in __connect
    self.dbapi_connection = connection = pool._invoke_creator(self)
                                         ^^^^^^^^^^^^^^^^^^^^^^^^^^
  File "/usr/lib/python3.11/site-packages/^^^^^^^^^^^^^^^^^^^^^^^
  File "/usr/lib/python3.11/unittest/loader.py", line 362, in _get_module_from_name
    __import__(name)
  File "/home/meta-bay/workspace/AirBnB_clone_v3/tests/test_models/test_state.py", line 8, in <module>
    import models
  File "/home/meta-bay/workspace/AirBnB_clone_v3/models/__init__.py", line 13, in <module>
    storage = DBStorage()
              ^^^^^^^^^^^
  File "/home/meta-bay/workspace/AirBnB_clone_v3/models/engine/db_storage.py", line 41, in __init__
    Base.metadata.drop_all(self.__engine)
  File "/usr/lib/python3.11/site-packages/sqlalchemy/sql/schema.py", line 4959, in drop_all
    bind._run_ddl_visitor(
  File "/usr/lib/python3.11/site-packages/sqlalchemy/engine/base.py", line 3227, in _run_ddl_visitor
    with self.begin() as conn:
         ^^^^^^^^^^^^
  File "/usr/lib/python3.11/site-packages/sqlalchemy/engine/base.py", line 3143, in begin
    conn = self.connect(close_with_result=close_with_result)
           ^^^^^^^^^^^^^^^^^^^^^^^^^^^^^^^^^^^^^^^^^^^^^^^^^
  File "/usr/lib/python3.11/site-packages/sqlalchemy/engine/base.py", line 3315, in connect
    return self._connection_cls(self, close_with_result=close_with_result)
           ^^^^^^^^^^^^^^^^^^^^^^^^^^^^^^^^^^^^^^^^^^^^^^^^^^^^^^^^^^^^^^^
  File "/usr/lib/python3.11/site-packages/sqlalchemy/engine/base.py", line 96, in __init__
    else engine.raw_connection()
         ^^^^^^^^^^^^^^^^^^^^^^^
  File "/usr/lib/python3.11/site-packages/sqlalchemy/engine/base.py", line 3394, in raw_connection
    return self._wrap_pool_connect(self.pool.connect, _connection)
           ^^^^^^^^^^^^^^^^^^^^^^^^^^^^^^^^^^^^^^^^^^^^^^^^^^^^^^^
  File "/usr/lib/python3.11/site-packages/sqlalchemy/engine/base.py", line 3364, in _wrap_pool_connect
    Connection._handle_dbapi_exception_noconnection(
  File "/usr/lib/python3.11/site-packages/sqlalchemy/engine/base.py", line 2198, in _handle_dbapi_exception_noconnection
    util.raise_(
  File "/usr/lib/python3.11/site-packages/sqlalchemy/util/compat.py", line 210, in raise_
    raise exception
  File "/usr/lib/python3.11/site-packages/sqlalchemy/engine/base.py", line 3361, in _wrap_pool_connect
    return fn()
           ^^^^
  File "/usr/lib/python3.11/site-packages/sqlalchemy/pool/base.py", line 325, in connect
    return _ConnectionFairy._checkout(self)
           ^^^^^^^^^^^^^^^^^^^^^^^^^^^^^^^^
  File "/usr/lib/python3.11/site-packages/sqlalchemy/pool/base.py", line 888, in _checkout
    fairy = _ConnectionRecord.checkout(pool)
            ^^^^^^^^^^^^^^^^^^^^^^^^^^^^^^^^
  File "/usr/lib/python3.11/site-packages/sqlalchemy/pool/base.py", line 491, in checkout
    rec = pool._do_get()
          ^^^^^^^^^^^^^^
  File "/usr/lib/python3.11/site-packages/sqlalchemy/pool/impl.py", line 145, in _do_get
    with util.safe_reraise():
  File "/usr/lib/python3.11/site-packages/sqlalchemy/util/langhelpers.py", line 70, in __exit__
    compat.raise_(
  File "/usr/lib/python3.11/site-packages/sqlalchemy/util/compat.py", line 210, in raise_
    raise exception
  File "/usr/lib/python3.11/site-packages/sqlalchemy/pool/impl.py", line 143, in _do_get
    return self._create_connection()
           ^^^^^^^^^^^^^^^^^^^^^^^^^
  File "/usr/lib/python3.11/site-packages/sqlalchemy/pool/base.py", line 271, in _create_connection
    return _ConnectionRecord(self)
           ^^^^^^^^^^^^^^^^^^^^^^^
  File "/usr/lib/python3.11/site-packages/sqlalchemy/pool/base.py", line 386, in __init__
    self.__connect()
  File "/usr/lib/python3.11/site-packages/sqlalchemy/pool/base.py", line 684, in __connect
    with util.safe_reraise():
  File "/usr/lib/python3.11/site-packages/sqlalchemy/util/langhelpers.py", line 70, in __exit__
    compat.raise_(
  File "/usr/lib/python3.11/site-packages/sqlalchemy/util/compat.py", line 210, in raise_
    raise exception
  File "/usr/lib/python3.11/site-packages/sqlalchemy/pool/base.py", line 680, in __connect
    self.dbapi_connection = connection = pool._invoke_creator(self)
                                         ^^^^^^^^^^^^^^^^^^^^^^^^^^
  File "/usr/lib/python3.11/site-packages/sqlalchemy/engine/create.py", line 578, in connect
    return dialect.connect(*cargs, **cparams)
           ^^^^^^^^^^^^^^^^^^^^^^^^^^^^^^^^^^
  File "/usr/lib/python3.11/site-packages/sqlalchemy/engine/default.py", line 598, in connect
    return self.dbapi.connect(*cargs, **cparams)
           ^^^^^^^^^^^^^^^^^^^^^^^^^^^^^^^^^^^^^
  File "/usr/lib/python3.11/site-packages/MySQLdb/__init__.py", line 123, in Connect
    return Connection(*args, **kwargs)
           ^^^^^^^^^^^^^^^^^^^^^^^^^^^
  File "/usr/lib/python3.11/site-packages/MySQLdb/connections.py", line 185, in __init__
    super().__init__(*args, **kwargs2)
sqlalchemy.exc.OperationalError: (MySQLdb.OperationalError) (1045, "Access denied for user 'hbnb_test'@'localhost' (using password: YES)")
(Background on this error at: https://sqlalche.me/e/14/e3q8)


======================================================================
ERROR: test_models.test_user (unittest.loader._FailedTest.test_models.test_user)
----------------------------------------------------------------------
ImportError: Failed to import test module: test_models.test_user
Traceback (most recent call last):
  File "/usr/lib/python3.11/site-packages/sqlalchemy/engine/base.py", line 3361, in _wrap_pool_connect
    return fn()
           ^^^^
  File "/usr/lib/python3.11/site-packages/sqlalchemy/pool/base.py", line 325, in connect
    return _ConnectionFairy._checkout(self)
           ^^^^^^^^^^^^^^^^^^^^^^^^^^^^^^^^
  File "/usr/lib/python3.11/site-packages/sqlalchemy/pool/base.py", line 888, in _checkout
    fairy = _ConnectionRecord.checkout(pool)
            ^^^^^^^^^^^^^^^^^^^^^^^^^^^^^^^^
  File "/usr/lib/python3.11/site-packages/sqlalchemy/pool/base.py", line 491, in checkout
    rec = pool._do_get()
          ^^^^^^^^^^^^^^
  File "/usr/lib/python3.11/site-packages/sqlalchemy/pool/impl.py", line 145, in _do_get
    with util.safe_reraise():
  File "/usr/lib/python3.11/site-packages/sqlalchemy/util/langhelpers.py", line 70, in __exit__
    compat.raise_(
  File "/usr/lib/python3.11/site-packages/sqlalchemy/util/compat.py", line 210, in raise_
    raise exception
  File "/usr/lib/python3.11/site-packages/sqlalchemy/pool/impl.py", line 143, in _do_get
    return self._create_connection()
           ^^^^^^^^^^^^^^^^^^^^^^^^^
  File "/usr/lib/python3.11/site-packages/sqlalchemy/pool/base.py", line 271, in _create_connection
    return _ConnectionRecord(self)
           ^^^^^^^^^^^^^^^^^^^^^^^
  File "/usr/lib/python3.11/site-packages/sqlalchemy/pool/base.py", line 386, in __init__
    self.__connect()
  File "/usr/lib/python3.11/site-packages/sqlalchemy/pool/base.py", line 684, in __connect
    with util.safe_reraise():
  File "/usr/lib/python3.11/site-packages/sqlalchemy/util/langhelpers.py", line 70, in __exit__
    compat.raise_(
  File "/usr/lib/python3.11/site-packages/sqlalchemy/util/compat.py", line 210, in raise_
    raise exception
  File "/usr/lib/python3.11/site-packages/sqlalchemy/pool/base.py", line 680, in __connect
    self.dbapi_connection = connection = pool._invoke_creator(self)
                                         ^^^^^^^^^^^^^^^^^^^^^^^^^^
  File "/usr/lib/python3.11/site-packages/sqlalchemy/engine/create.py", line 578, in connect
    return dialect.connect(*cargs, **cparams)
           ^^^^^^^^^^^^^^^^^^^^^^^^^^^^^^^^^^
  File "/usr/lib/python3.11/site-packages/sqlalchemy/engine/default.py", line 598, in connect
    return self.dbapi.connect(*cargs, **cparams)
           ^^^^^^^^^^^^^^^^^^^^^^^^^^^^^^^^^^^^^
  File "/usr/lib/python3.11/site-packages/MySQLdb/__init__.py", line 123, in Connect
    return Connection(*args, **kwargs)
           ^^^^^^^^^^^^^^^^^^^^^^^^^^^
  File "/usr/lib/python3.11/site-packages/MySQLdb/connections.py", line 185, in __init__
    super().__init__(*args, **kwargs2)
MySQLdb.OperationalError: (1045, "Access denied for user 'hbnb_test'@'localhost' (using password: YES)")

The above exception was the direct cause of the following exception:

Traceback (most recent call last):
  File "/usr/lib/python3.11/unittest/loader.py", line 419, in _find_sqlalchemy/engine/create.py", line 578, in connect
    return dialect.connect(*cargs, **cparams)
           ^^^^^^^^^^^^^^^^^^^^^^^^^^^^^^^^^^
  File "/usr/lib/python3.11/site-packages/sqlalchemy/engine/default.py", line 598, in connect
    return self.dbapi.connect(*cargs, **cparams)
           ^^^^^^^^^^^^^^^^^^^^^^^^^^^^^^^^^^^^^
  File "/usr/lib/python3.11/site-packages/MySQLdb/__init__.py", line 123, in Connect
    return Connection(*args, **kwargs)
           ^^^^^^^^^^^^^^^^^^^^^^^^^^^
  File "/usr/lib/python3.11/site-packages/MySQLdb/connections.py", line 185, in __init__
    super().__init__(*args, **kwargs2)
sqlalchemy.exc.OperationalError: (MySQLdb.OperationalError) (1045, "Access denied for user 'hbnb_test'@'localhost' (using password: YES)")
(Background on this error at: https://sqlalche.me/e/14/e3q8)


======================================================================
ERROR: test_models.test_user (unittest.loader._FailedTest.test_models.test_user)
----------------------------------------------------------------------
ImportError: Failed to import test module: test_models.test_user
Traceback (most recent call last):
  File "/usr/lib/python3.11/site-packages/sqlalchemy/engine/base.py", line 3361, in _wrap_pool_connect
    return fn()
           ^^^^
  File "/usr/lib/python3.11/site-packages/sqlalchemy/pool/base.py", line 325, in connect
    return _ConnectionFairy._checkout(self)
           ^^^^^^^^^^^^^^^^^^^^^^^^^^^^^^^^
  File "/usr/lib/python3.11/site-packages/sqlalchemy/pool/base.py", line 888, in _checkout
    fairy = _ConnectionRecord.checkout(pool)
            ^^^^^^^^^^^^^^^^^^^^^^^^^^^^^^^^
  File "/usr/lib/python3.11/site-packages/sqlalchemy/pool/base.py", line 491, in checkout
    rec = pool._do_get()
          ^^^^^^^^^^^^^^
  File "/usr/lib/python3.11/site-packages/sqlalchemy/pool/impl.py", line 145, in _do_get
    with util.safe_reraise():
  File "/usr/lib/python3.11/site-packages/sqlalchemy/util/langhelpers.py", line 70, in __exit__
    compat.raise_(
  File "/usr/lib/python3.11/site-packages/sqlalchemy/util/compat.py", line 210, in raise_
    raise exception
  File "/usr/lib/python3.11/site-packages/sqlalchemy/pool/impl.py", line 143, in _do_get
    return self._create_connection()
           ^^^^^^^^^^^^^^^^^^^^^^^^^
  File "/usr/lib/python3.11/site-packages/sqlalchemy/pool/base.py", line 271, in _create_connection
    return _ConnectionRecord(self)
           ^^^^^^^^^^^^^^^^^^^^^^^
  File "/usr/lib/python3.11/site-packages/sqlalchemy/pool/base.py", line 386, in __init__
    self.__connect()
  File "/usr/lib/python3.11/site-packages/sqlalchemy/pool/base.py", line 684, in __connect
    with util.safe_reraise():
  File "/usr/lib/python3.11/site-packages/sqlalchemy/util/langhelpers.py", line 70, in __exit__
    compat.raise_(
  File "/usr/lib/python3.11/site-packages/sqlalchemy/util/compat.py", line 210, in raise_
    raise exception
  File "/usr/lib/python3.11/site-packages/sqlalchemy/pool/base.py", line 680, in __connect
    self.dbapi_connection = connection = pool._invoke_creator(self)
                                         ^^^^^^^^^^^^^^^^^^^^^^^^^^
  File "/usr/lib/python3.11/site-packages/sqlalchemy/engine/create.py", line 578, in connect
    return dialect.connect(*cargs, **cparams)
           ^^^^^^^^^^^^^^^^^^^^^^^^^^^^^^^^^^
  File "/usr/lib/python3.11/site-packages/sqlalchemy/engine/default.py", line 598, in connect
    return self.dbapi.connect(*cargs, **cparams)
           ^^^^^^^^^^^^^^^^^^^^^^^^^^^^^^^^^^^^^
  File "/usr/lib/python3.11/site-packages/MySQLdb/__init__.py", line 123, in Connect
    return Connection(*args, **kwargs)
           ^^^^^^^^^^^^^^^^^^^^^^^^^^^
  File "/usr/lib/python3.11/site-packages/MySQLdb/connections.py", line 185, in __init__
    super().__init__(*args, **kwargs2)
MySQLdb.OperationalError: (1045, "Access denied for user 'hbnb_test'@'localhost' (using password: YES)")

The above exception was the direct cause of the following exception:

Traceback (most recent call last):
  File "/usr/lib/python3.11/unittest/loader.py", line 419, in _find_test_path
    module = self._get_module_from_name(name)
             ^^^^^^^^^^^^^^^^^^^^^^^^^^^^^^^^
  File "/usr/lib/python3.11/unittest/loader.py", line 362, in _get_module_from_name
    __import__(name)
  File "/home/meta-bay/workspace/AirBnB_clone_v3/tests/test_models/test_user.py", line 8, in <module>
    import models
  File "/home/meta-bay/workspace/AirBnB_clone_v3/models/__init__.py", line 13, in <module>
    storage = DBStorage()
              ^^^^^^^^^^^
  File "/home/meta-bay/workspace/AirBnB_clone_v3/models/engine/db_storage.py", line 41, in __init__
    Base.metadata.drop_all(self.__engine)
  File "/usr/lib/python3.11/site-packages/sqlalchemy/sql/schema.py", line 4959, in drop_all
    bind._run_ddl_visitor(
  File "/usr/lib/python3.11/site-packages/sqlalchemy/engine/base.py", line 3227, in _run_ddl_visitor
    with self.begin() as conn:
         ^^^^^^^^^^^^
  File "/usr/lib/python3.11/site-packages/sqlalchemy/engine/base.py", line 3143, in begin
    conn = self.connect(close_with_result=close_with_result)
           ^^^^^^^^^^^^^^^^^^^^^^^^^^^^^^^^^^^^^^^^^^^^^^^^^
  File "/usr/lib/python3.11/site-packages/sqlalchemy/engine/base.py", line 3315, in connect
    return self._connection_cls(self, close_with_result=close_with_result)
           ^^^^^^^^^^^^^^^^^^^^^^^^^^^^^^^^^^^^^^^^^^^^^^^^^^^^^^^^^^^^^^^
  File "/usr/lib/python3.11/site-packages/sqlalchemy/engine/base.py", line 96, in __init__
    else engine.raw_connection()
         ^^^^^^^^^^^^^^^^^^^^^^^
  File "/usr/lib/python3.11/site-packages/sqlalchemy/engine/base.py", line 3394, in raw_connection
    return self._wrap_pool_connect(self.pool.connect, _connection)
           ^^^^^^^^^^^^^^^^^^^^^^^^^^^^^^^^^^^^^^^^^^^^^^^^^^^^^^^
  File "/usr/lib/python3.11/site-packages/sqlalchemy/engine/base.py", line 3364, in _wrap_pool_connect
    Connection._handle_dbapi_exception_noconnection(
  File "/usr/lib/python3.11/site-packages/sqlalchemy/engine/base.py", line 2198, in _handle_dbapi_exception_noconnection
    util.raise_(
  File "/usr/lib/python3.11/site-packages/sqlalchemy/util/compat.py", line 210, in raise_
    raise exception
  File "/usr/lib/python3.11/site-packages/sqlalchemy/engine/base.py", line 3361, in _wrap_pool_connect
    return fn()
           ^^^^
  File "/usr/lib/python3.11/site-packages/sqlalchemy/pool/base.py", line 325, in connect
    return _ConnectionFairy._checkout(self)
           ^^^^^^^^^^^^^^^^^^^^^^^^^^^^^^^^
  File "/usr/lib/python3.11/site-packages/sqlalchemy/pool/base.py", line 888, in _checkout
    fairy = _ConnectionRecord.checkout(pool)
            ^^^^^^^^^^^^^^^^^^^^^^^^^^^^^^^^
  File "/usr/lib/python3.11/site-packages/sqlalchemy/pool/base.py", line 491, in checkout
    rec = pool._do_get()
          ^^^^^^^^^^^^^^
  File "/usr/lib/python3.11/site-packages/sqlalchemy/pool/impl.py", line 145, in _do_get
    with util.safe_reraise():
  File "/usr/lib/python3.11/site-packages/sqlalchemy/util/langhelpers.py", line 70, in __exit__
    compat.raise_(
  File "/usr/lib/python3.11/site-packages/sqlalchemy/util/compat.py", line 210, in raise_
    raise exception
  File "/usr/lib/python3.11/site-packages/sqlalchemy/pool/impl.py", line 143, in _do_get
    return self._create_connection()
           ^^^^^^^^^^^^^^^^^^^^^^^^^
  File "/usr/lib/python3.11/site-packages/sqlalchemy/pool/base.py", line 271, in _create_connection
    return _ConnectionRecord(self)
           ^^^^^^^^^^^^^^^^^^^^^^^
  File "/usr/lib/python3.11/site-packages/sqlalchemy/pool/base.py", line 386, in __init__
    self.__connect()
  File "/usr/lib/python3.11/site-packages/sqlalchemy/pool/base.py", line 684, in __connect
    with util.safe_reraise():
  File "/usr/lib/python3.11/site-packages/sqlalchemy/util/langhelpers.py", line 70, in __exit__
    compat.raise_(
  File "/usr/lib/python3.11/site-packages/sqlalchemy/util/compat.py", line 210, in raise_
    raise exception
  File "/usr/lib/python3.11/site-packages/sqlalchemy/pool/base.py", line 680, in __connect
    self.dbapi_connection = connection = pool._invoke_creator(self)
                                 test_path
    module = self._get_module_from_name(name)
             ^^^^^^^^^^^^^^^^^^^^^^^^^^^^^^^^
  File "/usr/lib/python3.11/unittest/loader.py", line 362, in _get_module_from_name
    __import__(name)
  File "/home/meta-bay/workspace/AirBnB_clone_v3/tests/test_models/test_user.py", line 8, in <module>
    import models
  File "/home/meta-bay/workspace/AirBnB_clone_v3/models/__init__.py", line 13, in <module>
    storage = DBStorage()
              ^^^^^^^^^^^
  File "/home/meta-bay/workspace/AirBnB_clone_v3/models/engine/db_storage.py", line 41, in __init__
    Base.metadata.drop_all(self.__engine)
  File "/usr/lib/python3.11/site-packages/sqlalchemy/sql/schema.py", line 4959, in drop_all
    bind._run_ddl_visitor(
  File "/usr/lib/python3.11/site-packages/sqlalchemy/engine/base.py", line 3227, in _run_ddl_visitor
    with self.begin() as conn:
         ^^^^^^^^^^^^
  File "/usr/lib/python3.11/site-packages/sqlalchemy/engine/base.py", line 3143, in begin
    conn = self.connect(close_with_result=close_with_result)
           ^^^^^^^^^^^^^^^^^^^^^^^^^^^^^^^^^^^^^^^^^^^^^^^^^
  File "/usr/lib/python3.11/site-packages/sqlalchemy/engine/base.py", line 3315, in connect
    return self._connection_cls(self, close_with_result=close_with_result)
           ^^^^^^^^^^^^^^^^^^^^^^^^^^^^^^^^^^^^^^^^^^^^^^^^^^^^^^^^^^^^^^^
  File "/usr/lib/python3.11/site-packages/sqlalchemy/engine/base.py", line 96, in __init__
    else engine.raw_connection()
         ^^^^^^^^^^^^^^^^^^^^^^^
  File "/usr/lib/python3.11/site-packages/sqlalchemy/engine/base.py", line 3394, in raw_connection
    return self._wrap_pool_connect(self.pool.connect, _connection)
           ^^^^^^^^^^^^^^^^^^^^^^^^^^^^^^^^^^^^^^^^^^^^^^^^^^^^^^^
  File "/usr/lib/python3.11/site-packages/sqlalchemy/engine/base.py", line 3364, in _wrap_pool_connect
    Connection._handle_dbapi_exception_noconnection(
  File "/usr/lib/python3.11/site-packages/sqlalchemy/engine/base.py", line 2198, in _handle_dbapi_exception_noconnection
    util.raise_(
  File "/usr/lib/python3.11/site-packages/sqlalchemy/util/compat.py", line 210, in raise_
    raise exception
  File "/usr/lib/python3.11/site-packages/sqlalchemy/engine/base.py", line 3361, in _wrap_pool_connect
    return fn()
           ^^^^
  File "/usr/lib/python3.11/site-packages/sqlalchemy/pool/base.py", line 325, in connect
    return _ConnectionFairy._checkout(self)
           ^^^^^^^^^^^^^^^^^^^^^^^^^^^^^^^^
  File "/usr/lib/python3.11/site-packages/sqlalchemy/pool/base.py", line 888, in _checkout
    fairy = _ConnectionRecord.checkout(pool)
            ^^^^^^^^^^^^^^^^^^^^^^^^^^^^^^^^
  File "/usr/lib/python3.11/site-packages/sqlalchemy/pool/base.py", line 491, in checkout
    rec = pool._do_get()
          ^^^^^^^^^^^^^^
  File "/usr/lib/python3.11/site-packages/sqlalchemy/pool/impl.py", line 145, in _do_get
    with util.safe_reraise():
  File "/usr/lib/python3.11/site-packages/sqlalchemy/util/langhelpers.py", line 70, in __exit__
    compat.raise_(
  File "/usr/lib/python3.11/site-packages/sqlalchemy/util/compat.py", line 210, in raise_
    raise exception
  File "/usr/lib/python3.11/site-packages/sqlalchemy/pool/impl.py", line 143, in _do_get
    return self._create_connection()
           ^^^^^^^^^^^^^^^^^^^^^^^^^
  File "/usr/lib/python3.11/site-packages/sqlalchemy/pool/base.py", line 271, in _create_connection
    return _ConnectionRecord(self)
           ^^^^^^^^^^^^^^^^^^^^^^^
  File "/usr/lib/python3.11/site-packages/sqlalchemy/pool/base.py", line 386, in __init__
    self.__connect()
  File "/usr/lib/python3.11/site-packages/sqlalchemy/pool/base.py", line 684, in __connect
    with util.safe_reraise():
  File "/usr/lib/python3.11/site-packages/sqlalchemy/util/langhelpers.py", line 70, in __exit__
    compat.raise_(
  File "/usr/lib/python3.11/site-packages/sqlalchemy/util/compat.py", line 210, in raise_
    raise exception
  File "/usr/lib/python3.11/site-packages/sqlalchemy/pool/base.py", line 680, in __connect
    self.dbapi_connection = connection = pool._invoke_creator(self)
                                         ^^^^^^^^^^^^^^^^^^^^^^^^^^
  File "/usr/lib/python3.11/site-packages/sqlalchemy/engine/create.py", line 578, in connect
    return dialect.connect(*cargs, **cparams)
           ^^^^^^^^^^^^^^^^^^^^^^^^^^^^^^^^^^
  File "/usr/lib/python3.11/site-packages/sqlalchemy/engine/default.py", line 598, in connect
    return self.dbapi.connect(*cargs, **cparams)
           ^^^^^^^^^^^^^^^^^^^^^^^^^^^^^^^^^^^^^
  File "/usr/lib/python3.11/site-packages/MySQLdb/__init__.py", line 123, in Connect
    return Connection(*args, **kwargs)
           ^^^^^^^^^^^^^^^^^^^^^^^^^^^
  File "/usr/lib/python3.11/site-packages/MySQLdb/connections.py", line 185, in __init__
    super().__init__(*args, **kwargs2)
sqlalchemy.exc.OperationalError: (MySQLdb.OperationalError) (1045, "Access denied for user 'hbnb_test'@'localhost' (using password: YES)")
(Background on this error at: https://sqlalche.me/e/14/e3q8)


----------------------------------------------------------------------
Ran 10 tests in 0.001s

FAILED (errors=10)
        ^^^^^^^^^^^^^^^^^^^^^^^^^^
  File "/usr/lib/python3.11/site-packages/sqlalchemy/engine/create.py", line 578, in connect
    return dialect.connect(*cargs, **cparams)
           ^^^^^^^^^^^^^^^^^^^^^^^^^^^^^^^^^^
  File "/usr/lib/python3.11/site-packages/sqlalchemy/engine/default.py", line 598, in connect
    return self.dbapi.connect(*cargs, **cparams)
           ^^^^^^^^^^^^^^^^^^^^^^^^^^^^^^^^^^^^^
  File "/usr/lib/python3.11/site-packages/MySQLdb/__init__.py", line 123, in Connect
    return Connection(*args, **kwargs)
           ^^^^^^^^^^^^^^^^^^^^^^^^^^^
  File "/usr/lib/python3.11/site-packages/MySQLdb/connections.py", line 185, in __init__
    super().__init__(*args, **kwargs2)
sqlalchemy.exc.OperationalError: (MySQLdb.OperationalError) (1045, "Access denied for user 'hbnb_test'@'localhost' (using password: YES)")
(Background on this error at: https://sqlalche.me/e/14/e3q8)


----------------------------------------------------------------------
Ran 10 tests in 0.001s

FAILED (errors=10)
